Workbook

Sheet Товары_очищенные
A1: Артикул (исх.) | B1: Наименование (исх.) | C1: Категория (исх.) | D1: Производитель (исх.) | E1: Цена_закупки (исх.) | F1: Цена_розница (исх.) | G1: Единица_измерения (исх.) | H1: Артикул | I1: Наименование | J1: Категория | K1: Производитель | L1: Цена закупки | M1: Цена розница | N1: Ед. изм. | O1: Проверка цены | P1: Проверка артикула
A2: №АРТ-001/24 | B2: Смартфон Apple iPhone 15 | C2: Смартфоны | D2: Apple | E2: 45 000,50 | F2: 79 990,00 | G2: шт | H2: ="АРТ-"&TEXT(VALUE(LEFT(SUBSTITUTE(SUBSTITUTE(SUBSTITUTE(SUBSTITUTE(TRIM(A2),"№",""),"АРТ-",""),"АРТ_",""),"АРТ",""),3)),"000") -> АРТ-001 | I2: =PROPER(TRIM(IFERROR(LEFT(B2,FIND("(",B2)-1),B2))) -> Смартфон Apple Iphone 15 | J2: =IFERROR(VLOOKUP(TRIM(C2),Справочники!$A$3:$B$13,2,0),"Нет в справочнике") -> Смартфоны | K2: =IF(LEN(TRIM(D2))<=3,UPPER(TRIM(D2)),PROPER(TRIM(D2))) -> Apple | L2: =ROUND(VALUE(SUBSTITUTE(SUBSTITUTE(SUBSTITUTE(SUBSTITUTE(SUBSTITUTE(TRIM(E2)," ",""),"руб.",""),"₽",""),",",""),".",""))/IF(OR(ISNUMBER(FIND(",",SUBSTITUTE(SUBSTITUTE(SUBSTITUTE(TRIM(E2)," ",""),"руб.",""),"₽",""))),ISNUMBER(FIND(".",SUBSTITUTE(SUBSTITUTE(SUBSTITUTE(TRIM(E2)," ",""),"руб.",""),"₽","")))),100,1),2) -> 45000.5 | M2: =ROUND(VALUE(SUBSTITUTE(SUBSTITUTE(SUBSTITUTE(SUBSTITUTE(SUBSTITUTE(TRIM(F2)," ",""),"руб.",""),"₽",""),",",""),".",""))/IF(OR(ISNUMBER(FIND(",",SUBSTITUTE(SUBSTITUTE(SUBSTITUTE(TRIM(F2)," ",""),"руб.",""),"₽",""))),ISNUMBER(FIND(".",SUBSTITUTE(SUBSTITUTE(SUBSTITUTE(TRIM(F2)," ",""),"руб.",""),"₽","")))),100,1),2) -> 79990 | N2: =IFERROR(VLOOKUP(TRIM(G2),Справочники!$P$3:$Q$7,2,0),"Нет в справочнике") -> шт. | O2: =IF(M2>=L2,"ОК","Розница ниже закупки") -> ОК | P2: =IF(COUNTIF($H$2:$H$502,H2)>1,"Повтор артикула","Уникальный") -> Уникальный
A3: АРТ_002 | B3: смартфон APPLE IPHONE 15 | C3: Телефоны | D3: Apple | E3: 44 500,00 | F3: 78 500,00 | G3: штука | H3: ="АРТ-"&TEXT(VALUE(LEFT(SUBSTITUTE(SUBSTITUTE(SUBSTITUTE(SUBSTITUTE(TRIM(A3),"№",""),"АРТ-",""),"АРТ_",""),"АРТ",""),3)),"000") -> АРТ-002 | I3: =PROPER(TRIM(IFERROR(LEFT(B3,FIND("(",B3)-1),B3))) -> Смартфон Apple Iphone 15 | J3: =IFERROR(VLOOKUP(TRIM(C3),Справочники!$A$3:$B$13,2,0),"Нет в справочнике") -> Смартфоны | K3: =IF(LEN(TRIM(D3))<=3,UPPER(TRIM(D3)),PROPER(TRIM(D3))) -> Apple | L3: =ROUND(VALUE(SUBSTITUTE(SUBSTITUTE(SUBSTITUTE(SUBSTITUTE(SUBSTITUTE(TRIM(E3)," ",""),"руб.",""),"₽",""),",",""),".",""))/IF(OR(ISNUMBER(FIND(",",SUBSTITUTE(SUBSTITUTE(SUBSTITUTE(TRIM(E3)," ",""),"руб.",""),"₽",""))),ISNUMBER(FIND(".",SUBSTITUTE(SUBSTITUTE(SUBSTITUTE(TRIM(E3)," ",""),"руб.",""),"₽","")))),100,1),2) -> 44500 | M3: =ROUND(VALUE(SUBSTITUTE(SUBSTITUTE(SUBSTITUTE(SUBSTITUTE(SUBSTITUTE(TRIM(F3)," ",""),"руб.",""),"₽",""),",",""),".",""))/IF(OR(ISNUMBER(FIND(",",SUBSTITUTE(SUBSTITUTE(SUBSTITUTE(TRIM(F3)," ",""),"руб.",""),"₽",""))),ISNUMBER(FIND(".",SUBSTITUTE(SUBSTITUTE(SUBSTITUTE(TRIM(F3)," ",""),"руб.",""),"₽","")))),100,1),2) -> 78500 | N3: =IFERROR(VLOOKUP(TRIM(G3),Справочники!$P$3:$Q$7,2,0),"Нет в справочнике") -> шт. | O3: =IF(M3>=L3,"ОК","Розница ниже закупки") -> ОК | P3: =IF(COUNTIF($H$2:$H$502,H3)>1,"Повтор артикула","Уникальный") -> Уникальный
A4: 003/24 | B4: Смартфон Apple iPhone 15 (Черный) | C4: Мобильные телефоны | D4: APPLE | E4: 43 800,00 | F4: 77 700 | G4: штуки | H4: ="АРТ-"&TEXT(VALUE(LEFT(SUBSTITUTE(SUBSTITUTE(SUBSTITUTE(SUBSTITUTE(TRIM(A4),"№",""),"АРТ-",""),"АРТ_",""),"АРТ",""),3)),"000") -> АРТ-003 | I4: =PROPER(TRIM(IFERROR(LEFT(B4,FIND("(",B4)-1),B4))) -> Смартфон Apple Iphone 15 | J4: =IFERROR(VLOOKUP(TRIM(C4),Справочники!$A$3:$B$13,2,0),"Нет в справочнике") -> Смартфоны | K4: =IF(LEN(TRIM(D4))<=3,UPPER(TRIM(D4)),PROPER(TRIM(D4))) -> Apple | L4: =ROUND(VALUE(SUBSTITUTE(SUBSTITUTE(SUBSTITUTE(SUBSTITUTE(SUBSTITUTE(TRIM(E4)," ",""),"руб.",""),"₽",""),",",""),".",""))/IF(OR(ISNUMBER(FIND(",",SUBSTITUTE(SUBSTITUTE(SUBSTITUTE(TRIM(E4)," ",""),"руб.",""),"₽",""))),ISNUMBER(FIND(".",SUBSTITUTE(SUBSTITUTE(SUBSTITUTE(TRIM(E4)," ",""),"руб.",""),"₽","")))),100,1),2) -> 43800 | M4: =ROUND(VALUE(SUBSTITUTE(SUBSTITUTE(SUBSTITUTE(SUBSTITUTE(SUBSTITUTE(TRIM(F4)," ",""),"руб.",""),"₽",""),",",""),".",""))/IF(OR(ISNUMBER(FIND(",",SUBSTITUTE(SUBSTITUTE(SUBSTITUTE(TRIM(F4)," ",""),"руб.",""),"₽",""))),ISNUMBER(FIND(".",SUBSTITUTE(SUBSTITUTE(SUBSTITUTE(TRIM(F4)," ",""),"руб.",""),"₽","")))),100,1),2) -> 77700 | N4: =IFERROR(VLOOKUP(TRIM(G4),Справочники!$P$3:$Q$7,2,0),"Нет в справочнике") -> шт. | O4: =IF(M4>=L4,"ОК","Розница ниже закупки") -> ОК | P4: =IF(COUNTIF($H$2:$H$502,H4)>1,"Повтор артикула","Уникальный") -> Уникальный
A5: №АРТ-004 | B5: Ноутбук ASUS ROG Zephyrus | C5: Ноутбуки | D5: ASUS | E5: 85 000 | F5: 129 999.99 | G5: шт. | H5: ="АРТ-"&TEXT(VALUE(LEFT(SUBSTITUTE(SUBSTITUTE(SUBSTITUTE(SUBSTITUTE(TRIM(A5),"№",""),"АРТ-",""),"АРТ_",""),"АРТ",""),3)),"000") -> АРТ-004 | I5: =PROPER(TRIM(IFERROR(LEFT(B5,FIND("(",B5)-1),B5))) -> Ноутбук Asus Rog Zephyrus | J5: =IFERROR(VLOOKUP(TRIM(C5),Справочники!$A$3:$B$13,2,0),"Нет в справочнике") -> Ноутбуки | K5: =IF(LEN(TRIM(D5))<=3,UPPER(TRIM(D5)),PROPER(TRIM(D5))) -> Asus | L5: =ROUND(VALUE(SUBSTITUTE(SUBSTITUTE(SUBSTITUTE(SUBSTITUTE(SUBSTITUTE(TRIM(E5)," ",""),"руб.",""),"₽",""),",",""),".",""))/IF(OR(ISNUMBER(FIND(",",SUBSTITUTE(SUBSTITUTE(SUBSTITUTE(TRIM(E5)," ",""),"руб.",""),"₽",""))),ISNUMBER(FIND(".",SUBSTITUTE(SUBSTITUTE(SUBSTITUTE(TRIM(E5)," ",""),"руб.",""),"₽","")))),100,1),2) -> 85000 | M5: =ROUND(VALUE(SUBSTITUTE(SUBSTITUTE(SUBSTITUTE(SUBSTITUTE(SUBSTITUTE(TRIM(F5)," ",""),"руб.",""),"₽",""),",",""),".",""))/IF(OR(ISNUMBER(FIND(",",SUBSTITUTE(SUBSTITUTE(SUBSTITUTE(TRIM(F5)," ",""),"руб.",""),"₽",""))),ISNUMBER(FIND(".",SUBSTITUTE(SUBSTITUTE(SUBSTITUTE(TRIM(F5)," ",""),"руб.",""),"₽","")))),100,1),2) -> 129999.99 | N5: =IFERROR(VLOOKUP(TRIM(G5),Справочники!$P$3:$Q$7,2,0),"Нет в справочнике") -> шт. | O5: =IF(M5>=L5,"ОК","Розница ниже закупки") -> ОК | P5: =IF(COUNTIF($H$2:$H$502,H5)>1,"Повтор артикула","Уникальный") -> Уникальный
A6: АРТ_005 | B6: ноутбук ASUS ROG Zephyrus | C6: Лэптопы | D6: asus | E6: 84 500,50 | F6: 128 500,00 | G6: шт | H6: ="АРТ-"&TEXT(VALUE(LEFT(SUBSTITUTE(SUBSTITUTE(SUBSTITUTE(SUBSTITUTE(TRIM(A6),"№",""),"АРТ-",""),"АРТ_",""),"АРТ",""),3)),"000") -> АРТ-005 | I6: =PROPER(TRIM(IFERROR(LEFT(B6,FIND("(",B6)-1),B6))) -> Ноутбук Asus Rog Zephyrus | J6: =IFERROR(VLOOKUP(TRIM(C6),Справочники!$A$3:$B$13,2,0),"Нет в справочнике") -> Ноутбуки | K6: =IF(LEN(TRIM(D6))<=3,UPPER(TRIM(D6)),PROPER(TRIM(D6))) -> Asus | L6: =ROUND(VALUE(SUBSTITUTE(SUBSTITUTE(SUBSTITUTE(SUBSTITUTE(SUBSTITUTE(TRIM(E6)," ",""),"руб.",""),"₽",""),",",""),".",""))/IF(OR(ISNUMBER(FIND(",",SUBSTITUTE(SUBSTITUTE(SUBSTITUTE(TRIM(E6)," ",""),"руб.",""),"₽",""))),ISNUMBER(FIND(".",SUBSTITUTE(SUBSTITUTE(SUBSTITUTE(TRIM(E6)," ",""),"руб.",""),"₽","")))),100,1),2) -> 84500.5 | M6: =ROUND(VALUE(SUBSTITUTE(SUBSTITUTE(SUBSTITUTE(SUBSTITUTE(SUBSTITUTE(TRIM(F6)," ",""),"руб.",""),"₽",""),",",""),".",""))/IF(OR(ISNUMBER(FIND(",",SUBSTITUTE(SUBSTITUTE(SUBSTITUTE(TRIM(F6)," ",""),"руб.",""),"₽",""))),ISNUMBER(FIND(".",SUBSTITUTE(SUBSTITUTE(SUBSTITUTE(TRIM(F6)," ",""),"руб.",""),"₽","")))),100,1),2) -> 128500 | N6: =IFERROR(VLOOKUP(TRIM(G6),Справочники!$P$3:$Q$7,2,0),"Нет в справочнике") -> шт. | O6: =IF(M6>=L6,"ОК","Розница ниже закупки") -> ОК | P6: =IF(COUNTIF($H$2:$H$502,H6)>1,"Повтор артикула","Уникальный") -> Уникальный
A7: 006-24 | B7: Ноутбук ASUS ROG Zephyrus (G14) | C7: Ноутбуки | D7: ASUS | E7: 86 000 | F7: 131 000 | G7: штука | H7: ="АРТ-"&TEXT(VALUE(LEFT(SUBSTITUTE(SUBSTITUTE(SUBSTITUTE(SUBSTITUTE(TRIM(A7),"№",""),"АРТ-",""),"АРТ_",""),"АРТ",""),3)),"000") -> АРТ-006 | I7: =PROPER(TRIM(IFERROR(LEFT(B7,FIND("(",B7)-1),B7))) -> Ноутбук Asus Rog Zephyrus | J7: =IFERROR(VLOOKUP(TRIM(C7),Справочники!$A$3:$B$13,2,0),"Нет в справочнике") -> Ноутбуки | K7: =IF(LEN(TRIM(D7))<=3,UPPER(TRIM(D7)),PROPER(TRIM(D7))) -> Asus | L7: =ROUND(VALUE(SUBSTITUTE(SUBSTITUTE(SUBSTITUTE(SUBSTITUTE(SUBSTITUTE(TRIM(E7)," ",""),"руб.",""),"₽",""),",",""),".",""))/IF(OR(ISNUMBER(FIND(",",SUBSTITUTE(SUBSTITUTE(SUBSTITUTE(TRIM(E7)," ",""),"руб.",""),"₽",""))),ISNUMBER(FIND(".",SUBSTITUTE(SUBSTITUTE(SUBSTITUTE(TRIM(E7)," ",""),"руб.",""),"₽","")))),100,1),2) -> 86000 | M7: =ROUND(VALUE(SUBSTITUTE(SUBSTITUTE(SUBSTITUTE(SUBSTITUTE(SUBSTITUTE(TRIM(F7)," ",""),"руб.",""),"₽",""),",",""),".",""))/IF(OR(ISNUMBER(FIND(",",SUBSTITUTE(SUBSTITUTE(SUBSTITUTE(TRIM(F7)," ",""),"руб.",""),"₽",""))),ISNUMBER(FIND(".",SUBSTITUTE(SUBSTITUTE(SUBSTITUTE(TRIM(F7)," ",""),"руб.",""),"₽","")))),100,1),2) -> 131000 | N7: =IFERROR(VLOOKUP(TRIM(G7),Справочники!$P$3:$Q$7,2,0),"Нет в справочнике") -> шт. | O7: =IF(M7>=L7,"ОК","Розница ниже закупки") -> ОК | P7: =IF(COUNTIF($H$2:$H$502,H7)>1,"Повтор артикула","Уникальный") -> Уникальный
A8: №АРТ-007 | B8: Смартфон Samsung Galaxy S24 | C8: Смартфоны | D8: Samsung | E8: 39 999,99 | F8: 69 999,00 | G8: шт. | H8: ="АРТ-"&TEXT(VALUE(LEFT(SUBSTITUTE(SUBSTITUTE(SUBSTITUTE(SUBSTITUTE(TRIM(A8),"№",""),"АРТ-",""),"АРТ_",""),"АРТ",""),3)),"000") -> АРТ-007 | I8: =PROPER(TRIM(IFERROR(LEFT(B8,FIND("(",B8)-1),B8))) -> Смартфон Samsung Galaxy S24 | J8: =IFERROR(VLOOKUP(TRIM(C8),Справочники!$A$3:$B$13,2,0),"Нет в справочнике") -> Смартфоны | K8: =IF(LEN(TRIM(D8))<=3,UPPER(TRIM(D8)),PROPER(TRIM(D8))) -> Samsung | L8: =ROUND(VALUE(SUBSTITUTE(SUBSTITUTE(SUBSTITUTE(SUBSTITUTE(SUBSTITUTE(TRIM(E8)," ",""),"руб.",""),"₽",""),",",""),".",""))/IF(OR(ISNUMBER(FIND(",",SUBSTITUTE(SUBSTITUTE(SUBSTITUTE(TRIM(E8)," ",""),"руб.",""),"₽",""))),ISNUMBER(FIND(".",SUBSTITUTE(SUBSTITUTE(SUBSTITUTE(TRIM(E8)," ",""),"руб.",""),"₽","")))),100,1),2) -> 39999.99 | M8: =ROUND(VALUE(SUBSTITUTE(SUBSTITUTE(SUBSTITUTE(SUBSTITUTE(SUBSTITUTE(TRIM(F8)," ",""),"руб.",""),"₽",""),",",""),".",""))/IF(OR(ISNUMBER(FIND(",",SUBSTITUTE(SUBSTITUTE(SUBSTITUTE(TRIM(F8)," ",""),"руб.",""),"₽",""))),ISNUMBER(FIND(".",SUBSTITUTE(SUBSTITUTE(SUBSTITUTE(TRIM(F8)," ",""),"руб.",""),"₽","")))),100,1),2) -> 69999 | N8: =IFERROR(VLOOKUP(TRIM(G8),Справочники!$P$3:$Q$7,2,0),"Нет в справочнике") -> шт. | O8: =IF(M8>=L8,"ОК","Розница ниже закупки") -> ОК | P8: =IF(COUNTIF($H$2:$H$502,H8)>1,"Повтор артикула","Уникальный") -> Уникальный
A9: АРТ_008 | B9: смартфон SAMSUNG GALAXY S24 | C9: Телефоны | D9: SAMSUNG | E9: 39 500 | F9: 68 900 | G9: штуки | H9: ="АРТ-"&TEXT(VALUE(LEFT(SUBSTITUTE(SUBSTITUTE(SUBSTITUTE(SUBSTITUTE(TRIM(A9),"№",""),"АРТ-",""),"АРТ_",""),"АРТ",""),3)),"000") -> АРТ-008 | I9: =PROPER(TRIM(IFERROR(LEFT(B9,FIND("(",B9)-1),B9))) -> Смартфон Samsung Galaxy S24 | J9: =IFERROR(VLOOKUP(TRIM(C9),Справочники!$A$3:$B$13,2,0),"Нет в справочнике") -> Смартфоны | K9: =IF(LEN(TRIM(D9))<=3,UPPER(TRIM(D9)),PROPER(TRIM(D9))) -> Samsung | L9: =ROUND(VALUE(SUBSTITUTE(SUBSTITUTE(SUBSTITUTE(SUBSTITUTE(SUBSTITUTE(TRIM(E9)," ",""),"руб.",""),"₽",""),",",""),".",""))/IF(OR(ISNUMBER(FIND(",",SUBSTITUTE(SUBSTITUTE(SUBSTITUTE(TRIM(E9)," ",""),"руб.",""),"₽",""))),ISNUMBER(FIND(".",SUBSTITUTE(SUBSTITUTE(SUBSTITUTE(TRIM(E9)," ",""),"руб.",""),"₽","")))),100,1),2) -> 39500 | M9: =ROUND(VALUE(SUBSTITUTE(SUBSTITUTE(SUBSTITUTE(SUBSTITUTE(SUBSTITUTE(TRIM(F9)," ",""),"руб.",""),"₽",""),",",""),".",""))/IF(OR(ISNUMBER(FIND(",",SUBSTITUTE(SUBSTITUTE(SUBSTITUTE(TRIM(F9)," ",""),"руб.",""),"₽",""))),ISNUMBER(FIND(".",SUBSTITUTE(SUBSTITUTE(SUBSTITUTE(TRIM(F9)," ",""),"руб.",""),"₽","")))),100,1),2) -> 68900 | N9: =IFERROR(VLOOKUP(TRIM(G9),Справочники!$P$3:$Q$7,2,0),"Нет в справочнике") -> шт. | O9: =IF(M9>=L9,"ОК","Розница ниже закупки") -> ОК | P9: =IF(COUNTIF($H$2:$H$502,H9)>1,"Повтор артикула","Уникальный") -> Уникальный
A10: 009/24 | B10: Смартфон Samsung Galaxy S24 (Синий) | C10: Мобильные телефоны | D10: Samsung | E10: 40 200 | F10: 70 500 | G10: шт | H10: ="АРТ-"&TEXT(VALUE(LEFT(SUBSTITUTE(SUBSTITUTE(SUBSTITUTE(SUBSTITUTE(TRIM(A10),"№",""),"АРТ-",""),"АРТ_",""),"АРТ",""),3)),"000") -> АРТ-009 | I10: =PROPER(TRIM(IFERROR(LEFT(B10,FIND("(",B10)-1),B10))) -> Смартфон Samsung Galaxy S24 | J10: =IFERROR(VLOOKUP(TRIM(C10),Справочники!$A$3:$B$13,2,0),"Нет в справочнике") -> Смартфоны | K10: =IF(LEN(TRIM(D10))<=3,UPPER(TRIM(D10)),PROPER(TRIM(D10))) -> Samsung | L10: =ROUND(VALUE(SUBSTITUTE(SUBSTITUTE(SUBSTITUTE(SUBSTITUTE(SUBSTITUTE(TRIM(E10)," ",""),"руб.",""),"₽",""),",",""),".",""))/IF(OR(ISNUMBER(FIND(",",SUBSTITUTE(SUBSTITUTE(SUBSTITUTE(TRIM(E10)," ",""),"руб.",""),"₽",""))),ISNUMBER(FIND(".",SUBSTITUTE(SUBSTITUTE(SUBSTITUTE(TRIM(E10)," ",""),"руб.",""),"₽","")))),100,1),2) -> 40200 | M10: =ROUND(VALUE(SUBSTITUTE(SUBSTITUTE(SUBSTITUTE(SUBSTITUTE(SUBSTITUTE(TRIM(F10)," ",""),"руб.",""),"₽",""),",",""),".",""))/IF(OR(ISNUMBER(FIND(",",SUBSTITUTE(SUBSTITUTE(SUBSTITUTE(TRIM(F10)," ",""),"руб.",""),"₽",""))),ISNUMBER(FIND(".",SUBSTITUTE(SUBSTITUTE(SUBSTITUTE(TRIM(F10)," ",""),"руб.",""),"₽","")))),100,1),2) -> 70500 | N10: =IFERROR(VLOOKUP(TRIM(G10),Справочники!$P$3:$Q$7,2,0),"Нет в справочнике") -> шт. | O10: =IF(M10>=L10,"ОК","Розница ниже закупки") -> ОК | P10: =IF(COUNTIF($H$2:$H$502,H10)>1,"Повтор артикула","Уникальный") -> Уникальный
A11: №АРТ-010 | B11: Планшет iPad Pro 12.9 | C11: Планшеты | D11: Apple | E11: 55 000 | F11: 89 900 | G11: шт. | H11: ="АРТ-"&TEXT(VALUE(LEFT(SUBSTITUTE(SUBSTITUTE(SUBSTITUTE(SUBSTITUTE(TRIM(A11),"№",""),"АРТ-",""),"АРТ_",""),"АРТ",""),3)),"000") -> АРТ-010 | I11: =PROPER(TRIM(IFERROR(LEFT(B11,FIND("(",B11)-1),B11))) -> Планшет Ipad Pro 12.9 | J11: =IFERROR(VLOOKUP(TRIM(C11),Справочники!$A$3:$B$13,2,0),"Нет в справочнике") -> Планшеты | K11: =IF(LEN(TRIM(D11))<=3,UPPER(TRIM(D11)),PROPER(TRIM(D11))) -> Apple | L11: =ROUND(VALUE(SUBSTITUTE(SUBSTITUTE(SUBSTITUTE(SUBSTITUTE(SUBSTITUTE(TRIM(E11)," ",""),"руб.",""),"₽",""),",",""),".",""))/IF(OR(ISNUMBER(FIND(",",SUBSTITUTE(SUBSTITUTE(SUBSTITUTE(TRIM(E11)," ",""),"руб.",""),"₽",""))),ISNUMBER(FIND(".",SUBSTITUTE(SUBSTITUTE(SUBSTITUTE(TRIM(E11)," ",""),"руб.",""),"₽","")))),100,1),2) -> 55000 | M11: =ROUND(VALUE(SUBSTITUTE(SUBSTITUTE(SUBSTITUTE(SUBSTITUTE(SUBSTITUTE(TRIM(F11)," ",""),"руб.",""),"₽",""),",",""),".",""))/IF(OR(ISNUMBER(FIND(",",SUBSTITUTE(SUBSTITUTE(SUBSTITUTE(TRIM(F11)," ",""),"руб.",""),"₽",""))),ISNUMBER(FIND(".",SUBSTITUTE(SUBSTITUTE(SUBSTITUTE(TRIM(F11)," ",""),"руб.",""),"₽","")))),100,1),2) -> 89900 | N11: =IFERROR(VLOOKUP(TRIM(G11),Справочники!$P$3:$Q$7,2,0),"Нет в справочнике") -> шт. | O11: =IF(M11>=L11,"ОК","Розница ниже закупки") -> ОК | P11: =IF(COUNTIF($H$2:$H$502,H11)>1,"Повтор артикула","Уникальный") -> Уникальный
A12: АРТ_011 | B12: планшет APPLE IPAD PRO 12.9 | C12: Планшеты | D12: apple | E12: 54 500 | F12: 88 500 | G12: штука | H12: ="АРТ-"&TEXT(VALUE(LEFT(SUBSTITUTE(SUBSTITUTE(SUBSTITUTE(SUBSTITUTE(TRIM(A12),"№",""),"АРТ-",""),"АРТ_",""),"АРТ",""),3)),"000") -> АРТ-011 | I12: =PROPER(TRIM(IFERROR(LEFT(B12,FIND("(",B12)-1),B12))) -> Планшет Apple Ipad Pro 12.9 | J12: =IFERROR(VLOOKUP(TRIM(C12),Справочники!$A$3:$B$13,2,0),"Нет в справочнике") -> Планшеты | K12: =IF(LEN(TRIM(D12))<=3,UPPER(TRIM(D12)),PROPER(TRIM(D12))) -> Apple | L12: =ROUND(VALUE(SUBSTITUTE(SUBSTITUTE(SUBSTITUTE(SUBSTITUTE(SUBSTITUTE(TRIM(E12)," ",""),"руб.",""),"₽",""),",",""),".",""))/IF(OR(ISNUMBER(FIND(",",SUBSTITUTE(SUBSTITUTE(SUBSTITUTE(TRIM(E12)," ",""),"руб.",""),"₽",""))),ISNUMBER(FIND(".",SUBSTITUTE(SUBSTITUTE(SUBSTITUTE(TRIM(E12)," ",""),"руб.",""),"₽","")))),100,1),2) -> 54500 | M12: =ROUND(VALUE(SUBSTITUTE(SUBSTITUTE(SUBSTITUTE(SUBSTITUTE(SUBSTITUTE(TRIM(F12)," ",""),"руб.",""),"₽",""),",",""),".",""))/IF(OR(ISNUMBER(FIND(",",SUBSTITUTE(SUBSTITUTE(SUBSTITUTE(TRIM(F12)," ",""),"руб.",""),"₽",""))),ISNUMBER(FIND(".",SUBSTITUTE(SUBSTITUTE(SUBSTITUTE(TRIM(F12)," ",""),"руб.",""),"₽","")))),100,1),2) -> 88500 | N12: =IFERROR(VLOOKUP(TRIM(G12),Справочники!$P$3:$Q$7,2,0),"Нет в справочнике") -> шт. | O12: =IF(M12>=L12,"ОК","Розница ниже закупки") -> ОК | P12: =IF(COUNTIF($H$2:$H$502,H12)>1,"Повтор артикула","Уникальный") -> Уникальный
A13: 012-24 | B13: Планшет Apple iPad Pro 12.9 (Wi-Fi) | C13: Планшеты | D13: Apple | E13: 56 000 | F13: 91 000 | G13: шт | H13: ="АРТ-"&TEXT(VALUE(LEFT(SUBSTITUTE(SUBSTITUTE(SUBSTITUTE(SUBSTITUTE(TRIM(A13),"№",""),"АРТ-",""),"АРТ_",""),"АРТ",""),3)),"000") -> АРТ-012 | I13: =PROPER(TRIM(IFERROR(LEFT(B13,FIND("(",B13)-1),B13))) -> Планшет Apple Ipad Pro 12.9 | J13: =IFERROR(VLOOKUP(TRIM(C13),Справочники!$A$3:$B$13,2,0),"Нет в справочнике") -> Планшеты | K13: =IF(LEN(TRIM(D13))<=3,UPPER(TRIM(D13)),PROPER(TRIM(D13))) -> Apple | L13: =ROUND(VALUE(SUBSTITUTE(SUBSTITUTE(SUBSTITUTE(SUBSTITUTE(SUBSTITUTE(TRIM(E13)," ",""),"руб.",""),"₽",""),",",""),".",""))/IF(OR(ISNUMBER(FIND(",",SUBSTITUTE(SUBSTITUTE(SUBSTITUTE(TRIM(E13)," ",""),"руб.",""),"₽",""))),ISNUMBER(FIND(".",SUBSTITUTE(SUBSTITUTE(SUBSTITUTE(TRIM(E13)," ",""),"руб.",""),"₽","")))),100,1),2) -> 56000 | M13: =ROUND(VALUE(SUBSTITUTE(SUBSTITUTE(SUBSTITUTE(SUBSTITUTE(SUBSTITUTE(TRIM(F13)," ",""),"руб.",""),"₽",""),",",""),".",""))/IF(OR(ISNUMBER(FIND(",",SUBSTITUTE(SUBSTITUTE(SUBSTITUTE(TRIM(F13)," ",""),"руб.",""),"₽",""))),ISNUMBER(FIND(".",SUBSTITUTE(SUBSTITUTE(SUBSTITUTE(TRIM(F13)," ",""),"руб.",""),"₽","")))),100,1),2) -> 91000 | N13: =IFERROR(VLOOKUP(TRIM(G13),Справочники!$P$3:$Q$7,2,0),"Нет в справочнике") -> шт. | O13: =IF(M13>=L13,"ОК","Розница ниже закупки") -> ОК | P13: =IF(COUNTIF($H$2:$H$502,H13)>1,"Повтор артикула","Уникальный") -> Уникальный
... A502: 501/24 | B502: Клавиатура Logitech POP Keys (Pink) | C502: Аксессуары | D502: LOGITECH | E502: 4 000 | F502: 6 800 | G502: шт | H502: ="АРТ-"&TEXT(VALUE(LEFT(SUBSTITUTE(SUBSTITUTE(SUBSTITUTE(SUBSTITUTE(TRIM(A502),"№",""),"АРТ-",""),"АРТ_",""),"АРТ",""),3)),"000") -> АРТ-501 | I502: =PROPER(TRIM(IFERROR(LEFT(B502,FIND("(",B502)-1),B502))) -> Клавиатура Logitech Pop Keys | J502: =IFERROR(VLOOKUP(TRIM(C502),Справочники!$A$3:$B$13,2,0),"Нет в справочнике") -> Аксессуары | K502: =IF(LEN(TRIM(D502))<=3,UPPER(TRIM(D502)),PROPER(TRIM(D502))) -> Logitech | L502: =ROUND(VALUE(SUBSTITUTE(SUBSTITUTE(SUBSTITUTE(SUBSTITUTE(SUBSTITUTE(TRIM(E502)," ",""),"руб.",""),"₽",""),",",""),".",""))/IF(OR(ISNUMBER(FIND(",",SUBSTITUTE(SUBSTITUTE(SUBSTITUTE(TRIM(E502)," ",""),"руб.",""),"₽",""))),ISNUMBER(FIND(".",SUBSTITUTE(SUBSTITUTE(SUBSTITUTE(TRIM(E502)," ",""),"руб.",""),"₽","")))),100,1),2) -> 4000 | M502: =ROUND(VALUE(SUBSTITUTE(SUBSTITUTE(SUBSTITUTE(SUBSTITUTE(SUBSTITUTE(TRIM(F502)," ",""),"руб.",""),"₽",""),",",""),".",""))/IF(OR(ISNUMBER(FIND(",",SUBSTITUTE(SUBSTITUTE(SUBSTITUTE(TRIM(F502)," ",""),"руб.",""),"₽",""))),ISNUMBER(FIND(".",SUBSTITUTE(SUBSTITUTE(SUBSTITUTE(TRIM(F502)," ",""),"руб.",""),"₽","")))),100,1),2) -> 6800 | N502: =IFERROR(VLOOKUP(TRIM(G502),Справочники!$P$3:$Q$7,2,0),"Нет в справочнике") -> шт. | O502: =IF(M502>=L502,"ОК","Розница ниже закупки") -> ОК | P502: =IF(COUNTIF($H$2:$H$502,H502)>1,"Повтор артикула","Уникальный") -> Уникальный

Sheet Поставщики_очищенные
A1: ID_поставщика (исх.) | B1: Название (исх.) | C1: ИНН (исх.) | D1: КПП (исх.) | E1: Телефон (исх.) | F1: Email (исх.) | G1: Адрес (исх.) | H1: ИНН | I1: Проверка ИНН | J1: Телефон | K1: Email | L1: Проверка Email | M1: Индекс | N1: Адрес
A2: P001 | B2: ООО ТехноСнаб | C2: 7708123456 | D2: 770801001 | E2: 8-903-123-45-67 | F2: info@tehnosnab.ru | G2: 125009 г.Москва ул.Тверская д.15 | H2: =SUBSTITUTE(SUBSTITUTE(TRIM(C2)," ",""),CHAR(160),"") -> 7708123456 | I2: =IF(AND(ISNUMBER(VALUE(H2)),OR(LEN(H2)=10,LEN(H2)=12)),"ОК","Ошибка ИНН") -> ОК | J2: =IF(LEN(SUBSTITUTE(SUBSTITUTE(SUBSTITUTE(SUBSTITUTE(SUBSTITUTE(E2,"+",""),"-","")," ",""),"(",""),")",""))<10,"Ошибка телефона","+7 ("&MID(RIGHT(SUBSTITUTE(SUBSTITUTE(SUBSTITUTE(SUBSTITUTE(SUBSTITUTE(E2,"+",""),"-","")," ",""),"(",""),")",""),10),1,3)&") "&MID(RIGHT(SUBSTITUTE(SUBSTITUTE(SUBSTITUTE(SUBSTITUTE(SUBSTITUTE(E2,"+",""),"-","")," ",""),"(",""),")",""),10),4,3)&"-"&MID(RIGHT(SUBSTITUTE(SUBSTITUTE(SUBSTITUTE(SUBSTITUTE(SUBSTITUTE(E2,"+",""),"-","")," ",""),"(",""),")",""),10),7,2)&"-"&RIGHT(SUBSTITUTE(SUBSTITUTE(SUBSTITUTE(SUBSTITUTE(SUBSTITUTE(E2,"+",""),"-","")," ",""),"(",""),")",""),2)) -> +7 (903) 123-45-67 | K2: =LOWER(SUBSTITUTE(TRIM(F2)," ","")) -> info@tehnosnab.ru | L2: =IF(AND(ISNUMBER(FIND("@",K2)),ISNUMBER(FIND(".",K2,FIND("@",K2)+2))),"ОК","Ошибка Email") -> ОК | M2: =IF(ISNUMBER(VALUE(LEFT(TRIM(G2),6))),LEFT(TRIM(G2),6),"") -> 125009 | N2: =SUBSTITUTE(SUBSTITUTE(SUBSTITUTE(SUBSTITUTE(SUBSTITUTE(SUBSTITUTE(SUBSTITUTE(SUBSTITUTE(TRIM(IF(M2="",G2,MID(TRIM(G2),7,200)))," ",", ",1)," д.",", д."),".д.","., д."),"г.","г. "),"ул.","ул. "),"д.","д. "),"пр.","пр. "),"пр. ,","пр.,") -> г. Москва, ул. Тверская, д. 15
A3: P002 | B3: ЗАО ЭлектроПром | C3: 7812345678123 | D3: 781201001 | E3: +7 903 234-56-78 | F3: zakaz@electroprom | G3: 191186 г.Санкт-Петербург Невский пр.д.28 | H3: =SUBSTITUTE(SUBSTITUTE(TRIM(C3)," ",""),CHAR(160),"") -> 7812345678123 | I3: =IF(AND(ISNUMBER(VALUE(H3)),OR(LEN(H3)=10,LEN(H3)=12)),"ОК","Ошибка ИНН") -> Ошибка ИНН | J3: =IF(LEN(SUBSTITUTE(SUBSTITUTE(SUBSTITUTE(SUBSTITUTE(SUBSTITUTE(E3,"+",""),"-","")," ",""),"(",""),")",""))<10,"Ошибка телефона","+7 ("&MID(RIGHT(SUBSTITUTE(SUBSTITUTE(SUBSTITUTE(SUBSTITUTE(SUBSTITUTE(E3,"+",""),"-","")," ",""),"(",""),")",""),10),1,3)&") "&MID(RIGHT(SUBSTITUTE(SUBSTITUTE(SUBSTITUTE(SUBSTITUTE(SUBSTITUTE(E3,"+",""),"-","")," ",""),"(",""),")",""),10),4,3)&"-"&MID(RIGHT(SUBSTITUTE(SUBSTITUTE(SUBSTITUTE(SUBSTITUTE(SUBSTITUTE(E3,"+",""),"-","")," ",""),"(",""),")",""),10),7,2)&"-"&RIGHT(SUBSTITUTE(SUBSTITUTE(SUBSTITUTE(SUBSTITUTE(SUBSTITUTE(E3,"+",""),"-","")," ",""),"(",""),")",""),2)) -> +7 (903) 234-56-78 | K3: =LOWER(SUBSTITUTE(TRIM(F3)," ","")) -> zakaz@electroprom | L3: =IF(AND(ISNUMBER(FIND("@",K3)),ISNUMBER(FIND(".",K3,FIND("@",K3)+2))),"ОК","Ошибка Email") -> Ошибка Email | M3: =IF(ISNUMBER(VALUE(LEFT(TRIM(G3),6))),LEFT(TRIM(G3),6),"") -> 191186 | N3: =SUBSTITUTE(SUBSTITUTE(SUBSTITUTE(SUBSTITUTE(SUBSTITUTE(SUBSTITUTE(SUBSTITUTE(SUBSTITUTE(TRIM(IF(M3="",G3,MID(TRIM(G3),7,200)))," ",", ",1)," д.",", д."),".д.","., д."),"г.","г. "),"ул.","ул. "),"д.","д. "),"пр.","пр. "),"пр. ,","пр.,") -> г. Санкт-Петербург, Невский пр., д. 28
A4: P003 | B4: ООО КомплектСервис | C4: 77098765 | D4: 770901001 | E4: 8 903 345 67 89 | F4: komplekt@mail.ru | G4: 127006 г.Москва ул.Петровка д.20 | H4: =SUBSTITUTE(SUBSTITUTE(TRIM(C4)," ",""),CHAR(160),"") -> 77098765 | I4: =IF(AND(ISNUMBER(VALUE(H4)),OR(LEN(H4)=10,LEN(H4)=12)),"ОК","Ошибка ИНН") -> Ошибка ИНН | J4: =IF(LEN(SUBSTITUTE(SUBSTITUTE(SUBSTITUTE(SUBSTITUTE(SUBSTITUTE(E4,"+",""),"-","")," ",""),"(",""),")",""))<10,"Ошибка телефона","+7 ("&MID(RIGHT(SUBSTITUTE(SUBSTITUTE(SUBSTITUTE(SUBSTITUTE(SUBSTITUTE(E4,"+",""),"-","")," ",""),"(",""),")",""),10),1,3)&") "&MID(RIGHT(SUBSTITUTE(SUBSTITUTE(SUBSTITUTE(SUBSTITUTE(SUBSTITUTE(E4,"+",""),"-","")," ",""),"(",""),")",""),10),4,3)&"-"&MID(RIGHT(SUBSTITUTE(SUBSTITUTE(SUBSTITUTE(SUBSTITUTE(SUBSTITUTE(E4,"+",""),"-","")," ",""),"(",""),")",""),10),7,2)&"-"&RIGHT(SUBSTITUTE(SUBSTITUTE(SUBSTITUTE(SUBSTITUTE(SUBSTITUTE(E4,"+",""),"-","")," ",""),"(",""),")",""),2)) -> +7 (903) 345-67-89 | K4: =LOWER(SUBSTITUTE(TRIM(F4)," ","")) -> komplekt@mail.ru | L4: =IF(AND(ISNUMBER(FIND("@",K4)),ISNUMBER(FIND(".",K4,FIND("@",K4)+2))),"ОК","Ошибка Email") -> ОК | M4: =IF(ISNUMBER(VALUE(LEFT(TRIM(G4),6))),LEFT(TRIM(G4),6),"") -> 127006 | N4: =SUBSTITUTE(SUBSTITUTE(SUBSTITUTE(SUBSTITUTE(SUBSTITUTE(SUBSTITUTE(SUBSTITUTE(SUBSTITUTE(TRIM(IF(M4="",G4,MID(TRIM(G4),7,200)))," ",", ",1)," д.",", д."),".д.","., д."),"г.","г. "),"ул.","ул. "),"д.","д. "),"пр.","пр. "),"пр. ,","пр.,") -> г. Москва, ул. Петровка, д. 20
A5: P004 | B5: АО ТехноИмпорт | C5: 7712345678 | D5: 771001001 | E5: +79034567890 | F5: import@techno | G5: 119019 г.Москва ул.Арбат д.12 | H5: =SUBSTITUTE(SUBSTITUTE(TRIM(C5)," ",""),CHAR(160),"") -> 7712345678 | I5: =IF(AND(ISNUMBER(VALUE(H5)),OR(LEN(H5)=10,LEN(H5)=12)),"ОК","Ошибка ИНН") -> ОК | J5: =IF(LEN(SUBSTITUTE(SUBSTITUTE(SUBSTITUTE(SUBSTITUTE(SUBSTITUTE(E5,"+",""),"-","")," ",""),"(",""),")",""))<10,"Ошибка телефона","+7 ("&MID(RIGHT(SUBSTITUTE(SUBSTITUTE(SUBSTITUTE(SUBSTITUTE(SUBSTITUTE(E5,"+",""),"-","")," ",""),"(",""),")",""),10),1,3)&") "&MID(RIGHT(SUBSTITUTE(SUBSTITUTE(SUBSTITUTE(SUBSTITUTE(SUBSTITUTE(E5,"+",""),"-","")," ",""),"(",""),")",""),10),4,3)&"-"&MID(RIGHT(SUBSTITUTE(SUBSTITUTE(SUBSTITUTE(SUBSTITUTE(SUBSTITUTE(E5,"+",""),"-","")," ",""),"(",""),")",""),10),7,2)&"-"&RIGHT(SUBSTITUTE(SUBSTITUTE(SUBSTITUTE(SUBSTITUTE(SUBSTITUTE(E5,"+",""),"-","")," ",""),"(",""),")",""),2)) -> +7 (903) 456-78-90 | K5: =LOWER(SUBSTITUTE(TRIM(F5)," ","")) -> import@techno | L5: =IF(AND(ISNUMBER(FIND("@",K5)),ISNUMBER(FIND(".",K5,FIND("@",K5)+2))),"ОК","Ошибка Email") -> Ошибка Email | M5: =IF(ISNUMBER(VALUE(LEFT(TRIM(G5),6))),LEFT(TRIM(G5),6),"") -> 119019 | N5: =SUBSTITUTE(SUBSTITUTE(SUBSTITUTE(SUBSTITUTE(SUBSTITUTE(SUBSTITUTE(SUBSTITUTE(SUBSTITUTE(TRIM(IF(M5="",G5,MID(TRIM(G5),7,200)))," ",", ",1)," д.",", д."),".д.","., д."),"г.","г. "),"ул.","ул. "),"д.","д. "),"пр.","пр. "),"пр. ,","пр.,") -> г. Москва, ул. Арбат, д. 12
A6: P005 | B6: ООО ТоргМастер | C6: 7801234567890 | D6: 780101001 | E6: 8-903-567-89-01 | F6: torg@master | G6: 192007 г.Санкт-Петербург пр.Обуховской Обороны д.120 | H6: =SUBSTITUTE(SUBSTITUTE(TRIM(C6)," ",""),CHAR(160),"") -> 7801234567890 | I6: =IF(AND(ISNUMBER(VALUE(H6)),OR(LEN(H6)=10,LEN(H6)=12)),"ОК","Ошибка ИНН") -> Ошибка ИНН | J6: =IF(LEN(SUBSTITUTE(SUBSTITUTE(SUBSTITUTE(SUBSTITUTE(SUBSTITUTE(E6,"+",""),"-","")," ",""),"(",""),")",""))<10,"Ошибка телефона","+7 ("&MID(RIGHT(SUBSTITUTE(SUBSTITUTE(SUBSTITUTE(SUBSTITUTE(SUBSTITUTE(E6,"+",""),"-","")," ",""),"(",""),")",""),10),1,3)&") "&MID(RIGHT(SUBSTITUTE(SUBSTITUTE(SUBSTITUTE(SUBSTITUTE(SUBSTITUTE(E6,"+",""),"-","")," ",""),"(",""),")",""),10),4,3)&"-"&MID(RIGHT(SUBSTITUTE(SUBSTITUTE(SUBSTITUTE(SUBSTITUTE(SUBSTITUTE(E6,"+",""),"-","")," ",""),"(",""),")",""),10),7,2)&"-"&RIGHT(SUBSTITUTE(SUBSTITUTE(SUBSTITUTE(SUBSTITUTE(SUBSTITUTE(E6,"+",""),"-","")," ",""),"(",""),")",""),2)) -> +7 (903) 567-89-01 | K6: =LOWER(SUBSTITUTE(TRIM(F6)," ","")) -> torg@master | L6: =IF(AND(ISNUMBER(FIND("@",K6)),ISNUMBER(FIND(".",K6,FIND("@",K6)+2))),"ОК","Ошибка Email") -> Ошибка Email | M6: =IF(ISNUMBER(VALUE(LEFT(TRIM(G6),6))),LEFT(TRIM(G6),6),"") -> 192007 | N6: =SUBSTITUTE(SUBSTITUTE(SUBSTITUTE(SUBSTITUTE(SUBSTITUTE(SUBSTITUTE(SUBSTITUTE(SUBSTITUTE(TRIM(IF(M6="",G6,MID(TRIM(G6),7,200)))," ",", ",1)," д.",", д."),".д.","., д."),"г.","г. "),"ул.","ул. "),"д.","д. "),"пр.","пр. "),"пр. ,","пр.,") -> г. Санкт-Петербург, пр. Обуховской Обороны, д. 120
A7: P006 | B7: ЗАО Техноресурс | C7: 77134567 | D7: 771101001 | E7: 8-903-678-90-12 | F7: resurs@techno.ru | G7: 119121 г.Москва ул.Плющиха д.25 | H7: =SUBSTITUTE(SUBSTITUTE(TRIM(C7)," ",""),CHAR(160),"") -> 77134567 | I7: =IF(AND(ISNUMBER(VALUE(H7)),OR(LEN(H7)=10,LEN(H7)=12)),"ОК","Ошибка ИНН") -> Ошибка ИНН | J7: =IF(LEN(SUBSTITUTE(SUBSTITUTE(SUBSTITUTE(SUBSTITUTE(SUBSTITUTE(E7,"+",""),"-","")," ",""),"(",""),")",""))<10,"Ошибка телефона","+7 ("&MID(RIGHT(SUBSTITUTE(SUBSTITUTE(SUBSTITUTE(SUBSTITUTE(SUBSTITUTE(E7,"+",""),"-","")," ",""),"(",""),")",""),10),1,3)&") "&MID(RIGHT(SUBSTITUTE(SUBSTITUTE(SUBSTITUTE(SUBSTITUTE(SUBSTITUTE(E7,"+",""),"-","")," ",""),"(",""),")",""),10),4,3)&"-"&MID(RIGHT(SUBSTITUTE(SUBSTITUTE(SUBSTITUTE(SUBSTITUTE(SUBSTITUTE(E7,"+",""),"-","")," ",""),"(",""),")",""),10),7,2)&"-"&RIGHT(SUBSTITUTE(SUBSTITUTE(SUBSTITUTE(SUBSTITUTE(SUBSTITUTE(E7,"+",""),"-","")," ",""),"(",""),")",""),2)) -> +7 (903) 678-90-12 | K7: =LOWER(SUBSTITUTE(TRIM(F7)," ","")) -> resurs@techno.ru | L7: =IF(AND(ISNUMBER(FIND("@",K7)),ISNUMBER(FIND(".",K7,FIND("@",K7)+2))),"ОК","Ошибка Email") -> ОК | M7: =IF(ISNUMBER(VALUE(LEFT(TRIM(G7),6))),LEFT(TRIM(G7),6),"") -> 119121 | N7: =SUBSTITUTE(SUBSTITUTE(SUBSTITUTE(SUBSTITUTE(SUBSTITUTE(SUBSTITUTE(SUBSTITUTE(SUBSTITUTE(TRIM(IF(M7="",G7,MID(TRIM(G7),7,200)))," ",", ",1)," д.",", д."),".д.","., д."),"г.","г. "),"ул.","ул. "),"д.","д. "),"пр.","пр. "),"пр. ,","пр.,") -> г. Москва, ул. Плющиха, д. 25
A8: P007 | B8: ООО ПрогрессПлюс | C8: 7802345678 | D8: 780201001 | E8: +7 903 789-01-23 | F8: progress@mail | G8: 197022 г.Санкт-Петербург ул.Профессора Попова д.37 | H8: =SUBSTITUTE(SUBSTITUTE(TRIM(C8)," ",""),CHAR(160),"") -> 7802345678 | I8: =IF(AND(ISNUMBER(VALUE(H8)),OR(LEN(H8)=10,LEN(H8)=12)),"ОК","Ошибка ИНН") -> ОК | J8: =IF(LEN(SUBSTITUTE(SUBSTITUTE(SUBSTITUTE(SUBSTITUTE(SUBSTITUTE(E8,"+",""),"-","")," ",""),"(",""),")",""))<10,"Ошибка телефона","+7 ("&MID(RIGHT(SUBSTITUTE(SUBSTITUTE(SUBSTITUTE(SUBSTITUTE(SUBSTITUTE(E8,"+",""),"-","")," ",""),"(",""),")",""),10),1,3)&") "&MID(RIGHT(SUBSTITUTE(SUBSTITUTE(SUBSTITUTE(SUBSTITUTE(SUBSTITUTE(E8,"+",""),"-","")," ",""),"(",""),")",""),10),4,3)&"-"&MID(RIGHT(SUBSTITUTE(SUBSTITUTE(SUBSTITUTE(SUBSTITUTE(SUBSTITUTE(E8,"+",""),"-","")," ",""),"(",""),")",""),10),7,2)&"-"&RIGHT(SUBSTITUTE(SUBSTITUTE(SUBSTITUTE(SUBSTITUTE(SUBSTITUTE(E8,"+",""),"-","")," ",""),"(",""),")",""),2)) -> +7 (903) 789-01-23 | K8: =LOWER(SUBSTITUTE(TRIM(F8)," ","")) -> progress@mail | L8: =IF(AND(ISNUMBER(FIND("@",K8)),ISNUMBER(FIND(".",K8,FIND("@",K8)+2))),"ОК","Ошибка Email") -> Ошибка Email | M8: =IF(ISNUMBER(VALUE(LEFT(TRIM(G8),6))),LEFT(TRIM(G8),6),"") -> 197022 | N8: =SUBSTITUTE(SUBSTITUTE(SUBSTITUTE(SUBSTITUTE(SUBSTITUTE(SUBSTITUTE(SUBSTITUTE(SUBSTITUTE(TRIM(IF(M8="",G8,MID(TRIM(G8),7,200)))," ",", ",1)," д.",", д."),".д.","., д."),"г.","г. "),"ул.","ул. "),"д.","д. "),"пр.","пр. "),"пр. ,","пр.,") -> г. Санкт-Петербург, ул. Профессора Попова, д. 37
A9: P008 | B9: АО ЭлектронСбыт | C9: 771456789012 | D9: 771201001 | E9: 8-903-890-12-34 | F9: electron@sbyt | G9: 109316 г.Москва ул.Таганская д.54 | H9: =SUBSTITUTE(SUBSTITUTE(TRIM(C9)," ",""),CHAR(160),"") -> 771456789012 | I9: =IF(AND(ISNUMBER(VALUE(H9)),OR(LEN(H9)=10,LEN(H9)=12)),"ОК","Ошибка ИНН") -> ОК | J9: =IF(LEN(SUBSTITUTE(SUBSTITUTE(SUBSTITUTE(SUBSTITUTE(SUBSTITUTE(E9,"+",""),"-","")," ",""),"(",""),")",""))<10,"Ошибка телефона","+7 ("&MID(RIGHT(SUBSTITUTE(SUBSTITUTE(SUBSTITUTE(SUBSTITUTE(SUBSTITUTE(E9,"+",""),"-","")," ",""),"(",""),")",""),10),1,3)&") "&MID(RIGHT(SUBSTITUTE(SUBSTITUTE(SUBSTITUTE(SUBSTITUTE(SUBSTITUTE(E9,"+",""),"-","")," ",""),"(",""),")",""),10),4,3)&"-"&MID(RIGHT(SUBSTITUTE(SUBSTITUTE(SUBSTITUTE(SUBSTITUTE(SUBSTITUTE(E9,"+",""),"-","")," ",""),"(",""),")",""),10),7,2)&"-"&RIGHT(SUBSTITUTE(SUBSTITUTE(SUBSTITUTE(SUBSTITUTE(SUBSTITUTE(E9,"+",""),"-","")," ",""),"(",""),")",""),2)) -> +7 (903) 890-12-34 | K9: =LOWER(SUBSTITUTE(TRIM(F9)," ","")) -> electron@sbyt | L9: =IF(AND(ISNUMBER(FIND("@",K9)),ISNUMBER(FIND(".",K9,FIND("@",K9)+2))),"ОК","Ошибка Email") -> Ошибка Email | M9: =IF(ISNUMBER(VALUE(LEFT(TRIM(G9),6))),LEFT(TRIM(G9),6),"") -> 109316 | N9: =SUBSTITUTE(SUBSTITUTE(SUBSTITUTE(SUBSTITUTE(SUBSTITUTE(SUBSTITUTE(SUBSTITUTE(SUBSTITUTE(TRIM(IF(M9="",G9,MID(TRIM(G9),7,200)))," ",", ",1)," д.",", д."),".д.","., д."),"г.","г. "),"ул.","ул. "),"д.","д. "),"пр.","пр. "),"пр. ,","пр.,") -> г. Москва, ул. Таганская, д. 54
A10: P009 | B10: ООО СмартТех | C10: 7803456789 | D10: 780301001 | E10: +79039012345 | F10: smart@tech | G10: 196084 г.Санкт-Петербург ул.Заставская д.22 | H10: =SUBSTITUTE(SUBSTITUTE(TRIM(C10)," ",""),CHAR(160),"") -> 7803456789 | I10: =IF(AND(ISNUMBER(VALUE(H10)),OR(LEN(H10)=10,LEN(H10)=12)),"ОК","Ошибка ИНН") -> ОК | J10: =IF(LEN(SUBSTITUTE(SUBSTITUTE(SUBSTITUTE(SUBSTITUTE(SUBSTITUTE(E10,"+",""),"-","")," ",""),"(",""),")",""))<10,"Ошибка телефона","+7 ("&MID(RIGHT(SUBSTITUTE(SUBSTITUTE(SUBSTITUTE(SUBSTITUTE(SUBSTITUTE(E10,"+",""),"-","")," ",""),"(",""),")",""),10),1,3)&") "&MID(RIGHT(SUBSTITUTE(SUBSTITUTE(SUBSTITUTE(SUBSTITUTE(SUBSTITUTE(E10,"+",""),"-","")," ",""),"(",""),")",""),10),4,3)&"-"&MID(RIGHT(SUBSTITUTE(SUBSTITUTE(SUBSTITUTE(SUBSTITUTE(SUBSTITUTE(E10,"+",""),"-","")," ",""),"(",""),")",""),10),7,2)&"-"&RIGHT(SUBSTITUTE(SUBSTITUTE(SUBSTITUTE(SUBSTITUTE(SUBSTITUTE(E10,"+",""),"-","")," ",""),"(",""),")",""),2)) -> +7 (903) 901-23-45 | K10: =LOWER(SUBSTITUTE(TRIM(F10)," ","")) -> smart@tech | L10: =IF(AND(ISNUMBER(FIND("@",K10)),ISNUMBER(FIND(".",K10,FIND("@",K10)+2))),"ОК","Ошибка Email") -> Ошибка Email | M10: =IF(ISNUMBER(VALUE(LEFT(TRIM(G10),6))),LEFT(TRIM(G10),6),"") -> 196084 | N10: =SUBSTITUTE(SUBSTITUTE(SUBSTITUTE(SUBSTITUTE(SUBSTITUTE(SUBSTITUTE(SUBSTITUTE(SUBSTITUTE(TRIM(IF(M10="",G10,MID(TRIM(G10),7,200)))," ",", ",1)," д.",", д."),".д.","., д."),"г.","г. "),"ул.","ул. "),"д.","д. "),"пр.","пр. "),"пр. ,","пр.,") -> г. Санкт-Петербург, ул. Заставская, д. 22
A11: P010 | B11: ЗАО ТехноПром | C11: 7715678901 | D11: 771301001 | E11: 8-903-012-34-56 | F11: prom@tehno | G11: 119334 г.Москва ул.Косыгина д.17 | H11: =SUBSTITUTE(SUBSTITUTE(TRIM(C11)," ",""),CHAR(160),"") -> 7715678901 | I11: =IF(AND(ISNUMBER(VALUE(H11)),OR(LEN(H11)=10,LEN(H11)=12)),"ОК","Ошибка ИНН") -> ОК | J11: =IF(LEN(SUBSTITUTE(SUBSTITUTE(SUBSTITUTE(SUBSTITUTE(SUBSTITUTE(E11,"+",""),"-","")," ",""),"(",""),")",""))<10,"Ошибка телефона","+7 ("&MID(RIGHT(SUBSTITUTE(SUBSTITUTE(SUBSTITUTE(SUBSTITUTE(SUBSTITUTE(E11,"+",""),"-","")," ",""),"(",""),")",""),10),1,3)&") "&MID(RIGHT(SUBSTITUTE(SUBSTITUTE(SUBSTITUTE(SUBSTITUTE(SUBSTITUTE(E11,"+",""),"-","")," ",""),"(",""),")",""),10),4,3)&"-"&MID(RIGHT(SUBSTITUTE(SUBSTITUTE(SUBSTITUTE(SUBSTITUTE(SUBSTITUTE(E11,"+",""),"-","")," ",""),"(",""),")",""),10),7,2)&"-"&RIGHT(SUBSTITUTE(SUBSTITUTE(SUBSTITUTE(SUBSTITUTE(SUBSTITUTE(E11,"+",""),"-","")," ",""),"(",""),")",""),2)) -> +7 (903) 012-34-56 | K11: =LOWER(SUBSTITUTE(TRIM(F11)," ","")) -> prom@tehno | L11: =IF(AND(ISNUMBER(FIND("@",K11)),ISNUMBER(FIND(".",K11,FIND("@",K11)+2))),"ОК","Ошибка Email") -> Ошибка Email | M11: =IF(ISNUMBER(VALUE(LEFT(TRIM(G11),6))),LEFT(TRIM(G11),6),"") -> 119334 | N11: =SUBSTITUTE(SUBSTITUTE(SUBSTITUTE(SUBSTITUTE(SUBSTITUTE(SUBSTITUTE(SUBSTITUTE(SUBSTITUTE(TRIM(IF(M11="",G11,MID(TRIM(G11),7,200)))," ",", ",1)," д.",", д."),".д.","., д."),"г.","г. "),"ул.","ул. "),"д.","д. "),"пр.","пр. "),"пр. ,","пр.,") -> г. Москва, ул. Косыгина, д. 17
A12: P011 | B12: ООО СервисПлюс | C12: 78045678 | D12: 780401001 | E12: 8-903-123-45-67 | F12: service@plus.ru | G12: 199178 г.Санкт-Петербург ул.Средний пр.В.О.д.78 | H12: =SUBSTITUTE(SUBSTITUTE(TRIM(C12)," ",""),CHAR(160),"") -> 78045678 | I12: =IF(AND(ISNUMBER(VALUE(H12)),OR(LEN(H12)=10,LEN(H12)=12)),"ОК","Ошибка ИНН") -> Ошибка ИНН | J12: =IF(LEN(SUBSTITUTE(SUBSTITUTE(SUBSTITUTE(SUBSTITUTE(SUBSTITUTE(E12,"+",""),"-","")," ",""),"(",""),")",""))<10,"Ошибка телефона","+7 ("&MID(RIGHT(SUBSTITUTE(SUBSTITUTE(SUBSTITUTE(SUBSTITUTE(SUBSTITUTE(E12,"+",""),"-","")," ",""),"(",""),")",""),10),1,3)&") "&MID(RIGHT(SUBSTITUTE(SUBSTITUTE(SUBSTITUTE(SUBSTITUTE(SUBSTITUTE(E12,"+",""),"-","")," ",""),"(",""),")",""),10),4,3)&"-"&MID(RIGHT(SUBSTITUTE(SUBSTITUTE(SUBSTITUTE(SUBSTITUTE(SUBSTITUTE(E12,"+",""),"-","")," ",""),"(",""),")",""),10),7,2)&"-"&RIGHT(SUBSTITUTE(SUBSTITUTE(SUBSTITUTE(SUBSTITUTE(SUBSTITUTE(E12,"+",""),"-","")," ",""),"(",""),")",""),2)) -> +7 (903) 123-45-67 | K12: =LOWER(SUBSTITUTE(TRIM(F12)," ","")) -> service@plus.ru | L12: =IF(AND(ISNUMBER(FIND("@",K12)),ISNUMBER(FIND(".",K12,FIND("@",K12)+2))),"ОК","Ошибка Email") -> ОК | M12: =IF(ISNUMBER(VALUE(LEFT(TRIM(G12),6))),LEFT(TRIM(G12),6),"") -> 199178 | N12: =SUBSTITUTE(SUBSTITUTE(SUBSTITUTE(SUBSTITUTE(SUBSTITUTE(SUBSTITUTE(SUBSTITUTE(SUBSTITUTE(TRIM(IF(M12="",G12,MID(TRIM(G12),7,200)))," ",", ",1)," д.",", д."),".д.","., д."),"г.","г. "),"ул.","ул. "),"д.","д. "),"пр.","пр. "),"пр. ,","пр.,") -> г. Санкт-Петербург, ул. Средний пр. В.О., д. 78
A13: P012 | B13: АО ТехноТрейд | C13: 7716789012 | D13: 771401001 | E13: 89032345678 | F13: trade@tehno | G13: 107113 г.Москва ул.Сокольнический вал д.3 | H13: =SUBSTITUTE(SUBSTITUTE(TRIM(C13)," ",""),CHAR(160),"") -> 7716789012 | I13: =IF(AND(ISNUMBER(VALUE(H13)),OR(LEN(H13)=10,LEN(H13)=12)),"ОК","Ошибка ИНН") -> ОК | J13: =IF(LEN(SUBSTITUTE(SUBSTITUTE(SUBSTITUTE(SUBSTITUTE(SUBSTITUTE(E13,"+",""),"-","")," ",""),"(",""),")",""))<10,"Ошибка телефона","+7 ("&MID(RIGHT(SUBSTITUTE(SUBSTITUTE(SUBSTITUTE(SUBSTITUTE(SUBSTITUTE(E13,"+",""),"-","")," ",""),"(",""),")",""),10),1,3)&") "&MID(RIGHT(SUBSTITUTE(SUBSTITUTE(SUBSTITUTE(SUBSTITUTE(SUBSTITUTE(E13,"+",""),"-","")," ",""),"(",""),")",""),10),4,3)&"-"&MID(RIGHT(SUBSTITUTE(SUBSTITUTE(SUBSTITUTE(SUBSTITUTE(SUBSTITUTE(E13,"+",""),"-","")," ",""),"(",""),")",""),10),7,2)&"-"&RIGHT(SUBSTITUTE(SUBSTITUTE(SUBSTITUTE(SUBSTITUTE(SUBSTITUTE(E13,"+",""),"-","")," ",""),"(",""),")",""),2)) -> +7 (903) 234-56-78 | K13: =LOWER(SUBSTITUTE(TRIM(F13)," ","")) -> trade@tehno | L13: =IF(AND(ISNUMBER(FIND("@",K13)),ISNUMBER(FIND(".",K13,FIND("@",K13)+2))),"ОК","Ошибка Email") -> Ошибка Email | M13: =IF(ISNUMBER(VALUE(LEFT(TRIM(G13),6))),LEFT(TRIM(G13),6),"") -> 107113 | N13: =SUBSTITUTE(SUBSTITUTE(SUBSTITUTE(SUBSTITUTE(SUBSTITUTE(SUBSTITUTE(SUBSTITUTE(SUBSTITUTE(TRIM(IF(M13="",G13,MID(TRIM(G13),7,200)))," ",", ",1)," д.",", д."),".д.","., д."),"г.","г. "),"ул.","ул. "),"д.","д. "),"пр.","пр. "),"пр. ,","пр.,") -> г. Москва, ул. Сокольнический вал, д. 3
... A51: P050 | B51: ЗАО ТехноПроект | C51: 7735678901 | D51: 773301001 | E51: 8-903-012-34-56 | F51: proekt@tehno | G51: 119435 г.Москва ул.Погодинская д.18 | H51: =SUBSTITUTE(SUBSTITUTE(TRIM(C51)," ",""),CHAR(160),"") -> 7735678901 | I51: =IF(AND(ISNUMBER(VALUE(H51)),OR(LEN(H51)=10,LEN(H51)=12)),"ОК","Ошибка ИНН") -> ОК | J51: =IF(LEN(SUBSTITUTE(SUBSTITUTE(SUBSTITUTE(SUBSTITUTE(SUBSTITUTE(E51,"+",""),"-","")," ",""),"(",""),")",""))<10,"Ошибка телефона","+7 ("&MID(RIGHT(SUBSTITUTE(SUBSTITUTE(SUBSTITUTE(SUBSTITUTE(SUBSTITUTE(E51,"+",""),"-","")," ",""),"(",""),")",""),10),1,3)&") "&MID(RIGHT(SUBSTITUTE(SUBSTITUTE(SUBSTITUTE(SUBSTITUTE(SUBSTITUTE(E51,"+",""),"-","")," ",""),"(",""),")",""),10),4,3)&"-"&MID(RIGHT(SUBSTITUTE(SUBSTITUTE(SUBSTITUTE(SUBSTITUTE(SUBSTITUTE(E51,"+",""),"-","")," ",""),"(",""),")",""),10),7,2)&"-"&RIGHT(SUBSTITUTE(SUBSTITUTE(SUBSTITUTE(SUBSTITUTE(SUBSTITUTE(E51,"+",""),"-","")," ",""),"(",""),")",""),2)) -> +7 (903) 012-34-56 | K51: =LOWER(SUBSTITUTE(TRIM(F51)," ","")) -> proekt@tehno | L51: =IF(AND(ISNUMBER(FIND("@",K51)),ISNUMBER(FIND(".",K51,FIND("@",K51)+2))),"ОК","Ошибка Email") -> Ошибка Email | M51: =IF(ISNUMBER(VALUE(LEFT(TRIM(G51),6))),LEFT(TRIM(G51),6),"") -> 119435 | N51: =SUBSTITUTE(SUBSTITUTE(SUBSTITUTE(SUBSTITUTE(SUBSTITUTE(SUBSTITUTE(SUBSTITUTE(SUBSTITUTE(TRIM(IF(M51="",G51,MID(TRIM(G51),7,200)))," ",", ",1)," д.",", д."),".д.","., д."),"г.","г. "),"ул.","ул. "),"д.","д. "),"пр.","пр. "),"пр. ,","пр.,") -> г. Москва, ул. Погодинская, д. 18

Sheet Продажи_очищенные
A1: Дата (исх.) | B1: Артикул (исх.) | C1: Количество (исх.) | D1: Цена_продажи (исх.) | E1: ID_клиента (исх.) | F1: ID_поставщика (исх.) | G1: Статус (исх.) | H1: Дата | I1: Артикул | J1: Количество | K1: Цена_продажи_руб | L1: Статус | M1: Дубликат | N1: Категория (каталог) | O1: Цена розница (каталог) | P1: Проверка цены
A2: 01/15/2025 | B2: №АРТ-045 | C2: 2 | D2: $100 | E2: C0001 | F2: P012 | G2: Завершен | H2: =DATE(VALUE(RIGHT(A2,4)),VALUE(LEFT(A2,2)),VALUE(MID(A2,4,2))) -> 45672 | I2: ="АРТ-"&TEXT(VALUE(LEFT(SUBSTITUTE(SUBSTITUTE(SUBSTITUTE(SUBSTITUTE(TRIM(B2),"№",""),"АРТ-",""),"АРТ_",""),"АРТ",""),3)),"000") -> АРТ-045 | J2: =VALUE(TRIM(SUBSTITUTE(SUBSTITUTE(TRIM(C2),"шт.",""),"шт",""))) -> 2 | K2: =VALUE(SUBSTITUTE(SUBSTITUTE(SUBSTITUTE(SUBSTITUTE(D2,"$",""),"€",""),"₽","")," ",""))*IF(ISNUMBER(FIND("$",D2)),Справочники!$H$3,IF(ISNUMBER(FIND("€",D2)),Справочники!$H$4,1)) -> 9500 | L2: =IFERROR(VLOOKUP(TRIM(G2),Справочники!$D$3:$E$13,2,0),"Нет в справочнике") -> Завершен | M2: =IF(COUNTIFS($H$2:H2,H2,$I$2:I2,I2,$E$2:E2,E2)>1,"Дубликат","") | N2: =IFERROR(VLOOKUP(I2,Товары_очищенные!$H$2:$J$502,3,0),"Нет в каталоге") -> Телевизоры | O2: =IFERROR(VLOOKUP(I2,Товары_очищенные!$H$2:$M$502,6,0),"") -> 137000 | P2: =IF(O2="","Нет в каталоге",IF(ABS(K2/O2-1)<=0.2,"ОК","Цена отличается от каталога")) -> Цена отличается от каталога
A3: 01/15/2025 | B3: АРТ_112 | C3: 1 | D3: €85 | E3: C0002 | F3: P007 | G3: завершен | H3: =DATE(VALUE(RIGHT(A3,4)),VALUE(LEFT(A3,2)),VALUE(MID(A3,4,2))) -> 45672 | I3: ="АРТ-"&TEXT(VALUE(LEFT(SUBSTITUTE(SUBSTITUTE(SUBSTITUTE(SUBSTITUTE(TRIM(B3),"№",""),"АРТ-",""),"АРТ_",""),"АРТ",""),3)),"000") -> АРТ-112 | J3: =VALUE(TRIM(SUBSTITUTE(SUBSTITUTE(TRIM(C3),"шт.",""),"шт",""))) -> 1 | K3: =VALUE(SUBSTITUTE(SUBSTITUTE(SUBSTITUTE(SUBSTITUTE(D3,"$",""),"€",""),"₽","")," ",""))*IF(ISNUMBER(FIND("$",D3)),Справочники!$H$3,IF(ISNUMBER(FIND("€",D3)),Справочники!$H$4,1)) -> 8500 | L3: =IFERROR(VLOOKUP(TRIM(G3),Справочники!$D$3:$E$13,2,0),"Нет в справочнике") -> Завершен | M3: =IF(COUNTIFS($H$2:H3,H3,$I$2:I3,I3,$E$2:E3,E3)>1,"Дубликат","") | N3: =IFERROR(VLOOKUP(I3,Товары_очищенные!$H$2:$J$502,3,0),"Нет в каталоге") -> Наушники | O3: =IFERROR(VLOOKUP(I3,Товары_очищенные!$H$2:$M$502,6,0),"") -> 34990 | P3: =IF(O3="","Нет в каталоге",IF(ABS(K3/O3-1)<=0.2,"ОК","Цена отличается от каталога")) -> Цена отличается от каталога
A4: 01/16/2025 | B4: 003/24 | C4: 3 шт. | D4: 7500 ₽ | E4: C0003 | F4: P023 | G4: completed | H4: =DATE(VALUE(RIGHT(A4,4)),VALUE(LEFT(A4,2)),VALUE(MID(A4,4,2))) -> 45673 | I4: ="АРТ-"&TEXT(VALUE(LEFT(SUBSTITUTE(SUBSTITUTE(SUBSTITUTE(SUBSTITUTE(TRIM(B4),"№",""),"АРТ-",""),"АРТ_",""),"АРТ",""),3)),"000") -> АРТ-003 | J4: =VALUE(TRIM(SUBSTITUTE(SUBSTITUTE(TRIM(C4),"шт.",""),"шт",""))) -> 3 | K4: =VALUE(SUBSTITUTE(SUBSTITUTE(SUBSTITUTE(SUBSTITUTE(D4,"$",""),"€",""),"₽","")," ",""))*IF(ISNUMBER(FIND("$",D4)),Справочники!$H$3,IF(ISNUMBER(FIND("€",D4)),Справочники!$H$4,1)) -> 7500 | L4: =IFERROR(VLOOKUP(TRIM(G4),Справочники!$D$3:$E$13,2,0),"Нет в справочнике") -> Завершен | M4: =IF(COUNTIFS($H$2:H4,H4,$I$2:I4,I4,$E$2:E4,E4)>1,"Дубликат","") | N4: =IFERROR(VLOOKUP(I4,Товары_очищенные!$H$2:$J$502,3,0),"Нет в каталоге") -> Смартфоны | O4: =IFERROR(VLOOKUP(I4,Товары_очищенные!$H$2:$M$502,6,0),"") -> 77700 | P4: =IF(O4="","Нет в каталоге",IF(ABS(K4/O4-1)<=0.2,"ОК","Цена отличается от каталога")) -> Цена отличается от каталога
A5: 01/16/2025 | B5: №АРТ-234 | C5: -1 | D5: $110 | E5: C0004 | F5: P045 | G5: отменен | H5: =DATE(VALUE(RIGHT(A5,4)),VALUE(LEFT(A5,2)),VALUE(MID(A5,4,2))) -> 45673 | I5: ="АРТ-"&TEXT(VALUE(LEFT(SUBSTITUTE(SUBSTITUTE(SUBSTITUTE(SUBSTITUTE(TRIM(B5),"№",""),"АРТ-",""),"АРТ_",""),"АРТ",""),3)),"000") -> АРТ-234 | J5: =VALUE(TRIM(SUBSTITUTE(SUBSTITUTE(TRIM(C5),"шт.",""),"шт",""))) -> -1 | K5: =VALUE(SUBSTITUTE(SUBSTITUTE(SUBSTITUTE(SUBSTITUTE(D5,"$",""),"€",""),"₽","")," ",""))*IF(ISNUMBER(FIND("$",D5)),Справочники!$H$3,IF(ISNUMBER(FIND("€",D5)),Справочники!$H$4,1)) -> 10450 | L5: =IFERROR(VLOOKUP(TRIM(G5),Справочники!$D$3:$E$13,2,0),"Нет в справочнике") -> Отменен | M5: =IF(COUNTIFS($H$2:H5,H5,$I$2:I5,I5,$E$2:E5,E5)>1,"Дубликат","") | N5: =IFERROR(VLOOKUP(I5,Товары_очищенные!$H$2:$J$502,3,0),"Нет в каталоге") -> Смартфоны | O5: =IFERROR(VLOOKUP(I5,Товары_очищенные!$H$2:$M$502,6,0),"") -> 44500 | P5: =IF(O5="","Нет в каталоге",IF(ABS(K5/O5-1)<=0.2,"ОК","Цена отличается от каталога")) -> Цена отличается от каталога
A6: 01/17/2025 | B6: АРТ_067 | C6: 2 шт | D6: €90 | E6: C0005 | F6: P008 | G6: canceled | H6: =DATE(VALUE(RIGHT(A6,4)),VALUE(LEFT(A6,2)),VALUE(MID(A6,4,2))) -> 45674 | I6: ="АРТ-"&TEXT(VALUE(LEFT(SUBSTITUTE(SUBSTITUTE(SUBSTITUTE(SUBSTITUTE(TRIM(B6),"№",""),"АРТ-",""),"АРТ_",""),"АРТ",""),3)),"000") -> АРТ-067 | J6: =VALUE(TRIM(SUBSTITUTE(SUBSTITUTE(TRIM(C6),"шт.",""),"шт",""))) -> 2 | K6: =VALUE(SUBSTITUTE(SUBSTITUTE(SUBSTITUTE(SUBSTITUTE(D6,"$",""),"€",""),"₽","")," ",""))*IF(ISNUMBER(FIND("$",D6)),Справочники!$H$3,IF(ISNUMBER(FIND("€",D6)),Справочники!$H$4,1)) -> 9000 | L6: =IFERROR(VLOOKUP(TRIM(G6),Справочники!$D$3:$E$13,2,0),"Нет в справочнике") -> Отменен | M6: =IF(COUNTIFS($H$2:H6,H6,$I$2:I6,I6,$E$2:E6,E6)>1,"Дубликат","") | N6: =IFERROR(VLOOKUP(I6,Товары_очищенные!$H$2:$J$502,3,0),"Нет в каталоге") -> Телевизоры | O6: =IFERROR(VLOOKUP(I6,Товары_очищенные!$H$2:$M$502,6,0),"") -> 109999 | P6: =IF(O6="","Нет в каталоге",IF(ABS(K6/O6-1)<=0.2,"ОК","Цена отличается от каталога")) -> Цена отличается от каталога
A7: 01/17/2025 | B7: 078-24 | C7: 1 | D7: 8000 ₽ | E7: C0006 | F7: P031 | G7: возврат | H7: =DATE(VALUE(RIGHT(A7,4)),VALUE(LEFT(A7,2)),VALUE(MID(A7,4,2))) -> 45674 | I7: ="АРТ-"&TEXT(VALUE(LEFT(SUBSTITUTE(SUBSTITUTE(SUBSTITUTE(SUBSTITUTE(TRIM(B7),"№",""),"АРТ-",""),"АРТ_",""),"АРТ",""),3)),"000") -> АРТ-078 | J7: =VALUE(TRIM(SUBSTITUTE(SUBSTITUTE(TRIM(C7),"шт.",""),"шт",""))) -> 1 | K7: =VALUE(SUBSTITUTE(SUBSTITUTE(SUBSTITUTE(SUBSTITUTE(D7,"$",""),"€",""),"₽","")," ",""))*IF(ISNUMBER(FIND("$",D7)),Справочники!$H$3,IF(ISNUMBER(FIND("€",D7)),Справочники!$H$4,1)) -> 8000 | L7: =IFERROR(VLOOKUP(TRIM(G7),Справочники!$D$3:$E$13,2,0),"Нет в справочнике") -> Возврат | M7: =IF(COUNTIFS($H$2:H7,H7,$I$2:I7,I7,$E$2:E7,E7)>1,"Дубликат","") | N7: =IFERROR(VLOOKUP(I7,Товары_очищенные!$H$2:$J$502,3,0),"Нет в каталоге") -> Аксессуары | O7: =IFERROR(VLOOKUP(I7,Товары_очищенные!$H$2:$M$502,6,0),"") -> 13500 | P7: =IF(O7="","Нет в каталоге",IF(ABS(K7/O7-1)<=0.2,"ОК","Цена отличается от каталога")) -> Цена отличается от каталога
A8: 01/18/2025 | B8: №АРТ-389 | C8: 3 | D8: $105 | E8: C0007 | F8: P019 | G8: Завершен | H8: =DATE(VALUE(RIGHT(A8,4)),VALUE(LEFT(A8,2)),VALUE(MID(A8,4,2))) -> 45675 | I8: ="АРТ-"&TEXT(VALUE(LEFT(SUBSTITUTE(SUBSTITUTE(SUBSTITUTE(SUBSTITUTE(TRIM(B8),"№",""),"АРТ-",""),"АРТ_",""),"АРТ",""),3)),"000") -> АРТ-389 | J8: =VALUE(TRIM(SUBSTITUTE(SUBSTITUTE(TRIM(C8),"шт.",""),"шт",""))) -> 3 | K8: =VALUE(SUBSTITUTE(SUBSTITUTE(SUBSTITUTE(SUBSTITUTE(D8,"$",""),"€",""),"₽","")," ",""))*IF(ISNUMBER(FIND("$",D8)),Справочники!$H$3,IF(ISNUMBER(FIND("€",D8)),Справочники!$H$4,1)) -> 9975 | L8: =IFERROR(VLOOKUP(TRIM(G8),Справочники!$D$3:$E$13,2,0),"Нет в справочнике") -> Завершен | M8: =IF(COUNTIFS($H$2:H8,H8,$I$2:I8,I8,$E$2:E8,E8)>1,"Дубликат","") | N8: =IFERROR(VLOOKUP(I8,Товары_очищенные!$H$2:$J$502,3,0),"Нет в каталоге") -> Телевизоры | O8: =IFERROR(VLOOKUP(I8,Товары_очищенные!$H$2:$M$502,6,0),"") -> 75000 | P8: =IF(O8="","Нет в каталоге",IF(ABS(K8/O8-1)<=0.2,"ОК","Цена отличается от каталога")) -> Цена отличается от каталога
A9: 01/18/2025 | B9: АРТ_156 | C9: 2 | D9: €95 | E9: C0008 | F9: P042 | G9: completed | H9: =DATE(VALUE(RIGHT(A9,4)),VALUE(LEFT(A9,2)),VALUE(MID(A9,4,2))) -> 45675 | I9: ="АРТ-"&TEXT(VALUE(LEFT(SUBSTITUTE(SUBSTITUTE(SUBSTITUTE(SUBSTITUTE(TRIM(B9),"№",""),"АРТ-",""),"АРТ_",""),"АРТ",""),3)),"000") -> АРТ-156 | J9: =VALUE(TRIM(SUBSTITUTE(SUBSTITUTE(TRIM(C9),"шт.",""),"шт",""))) -> 2 | K9: =VALUE(SUBSTITUTE(SUBSTITUTE(SUBSTITUTE(SUBSTITUTE(D9,"$",""),"€",""),"₽","")," ",""))*IF(ISNUMBER(FIND("$",D9)),Справочники!$H$3,IF(ISNUMBER(FIND("€",D9)),Справочники!$H$4,1)) -> 9500 | L9: =IFERROR(VLOOKUP(TRIM(G9),Справочники!$D$3:$E$13,2,0),"Нет в справочнике") -> Завершен | M9: =IF(COUNTIFS($H$2:H9,H9,$I$2:I9,I9,$E$2:E9,E9)>1,"Дубликат","") | N9: =IFERROR(VLOOKUP(I9,Товары_очищенные!$H$2:$J$502,3,0),"Нет в каталоге") -> Наушники | O9: =IFERROR(VLOOKUP(I9,Товары_очищенные!$H$2:$M$502,6,0),"") -> 17800 | P9: =IF(O9="","Нет в каталоге",IF(ABS(K9/O9-1)<=0.2,"ОК","Цена отличается от каталога")) -> Цена отличается от каталога
A10: 01/19/2025 | B10: 251/24 | C10: 1 шт. | D10: 6500 ₽ | E10: C0009 | F10: P005 | G10: завершен | H10: =DATE(VALUE(RIGHT(A10,4)),VALUE(LEFT(A10,2)),VALUE(MID(A10,4,2))) -> 45676 | I10: ="АРТ-"&TEXT(VALUE(LEFT(SUBSTITUTE(SUBSTITUTE(SUBSTITUTE(SUBSTITUTE(TRIM(B10),"№",""),"АРТ-",""),"АРТ_",""),"АРТ",""),3)),"000") -> АРТ-251 | J10: =VALUE(TRIM(SUBSTITUTE(SUBSTITUTE(TRIM(C10),"шт.",""),"шт",""))) -> 1 | K10: =VALUE(SUBSTITUTE(SUBSTITUTE(SUBSTITUTE(SUBSTITUTE(D10,"$",""),"€",""),"₽","")," ",""))*IF(ISNUMBER(FIND("$",D10)),Справочники!$H$3,IF(ISNUMBER(FIND("€",D10)),Справочники!$H$4,1)) -> 6500 | L10: =IFERROR(VLOOKUP(TRIM(G10),Справочники!$D$3:$E$13,2,0),"Нет в справочнике") -> Завершен | M10: =IF(COUNTIFS($H$2:H10,H10,$I$2:I10,I10,$E$2:E10,E10)>1,"Дубликат","") | N10: =IFERROR(VLOOKUP(I10,Товары_очищенные!$H$2:$J$502,3,0),"Нет в каталоге") -> Часы | O10: =IFERROR(VLOOKUP(I10,Товары_очищенные!$H$2:$M$502,6,0),"") -> 53500 | P10: =IF(O10="","Нет в каталоге",IF(ABS(K10/O10-1)<=0.2,"ОК","Цена отличается от каталога")) -> Цена отличается от каталога
A11: 01/19/2025 | B11: №АРТ-023 | C11: -2 | D11: $115 | E11: C0010 | F11: P036 | G11: Отменен | H11: =DATE(VALUE(RIGHT(A11,4)),VALUE(LEFT(A11,2)),VALUE(MID(A11,4,2))) -> 45676 | I11: ="АРТ-"&TEXT(VALUE(LEFT(SUBSTITUTE(SUBSTITUTE(SUBSTITUTE(SUBSTITUTE(TRIM(B11),"№",""),"АРТ-",""),"АРТ_",""),"АРТ",""),3)),"000") -> АРТ-023 | J11: =VALUE(TRIM(SUBSTITUTE(SUBSTITUTE(TRIM(C11),"шт.",""),"шт",""))) -> -2 | K11: =VALUE(SUBSTITUTE(SUBSTITUTE(SUBSTITUTE(SUBSTITUTE(D11,"$",""),"€",""),"₽","")," ",""))*IF(ISNUMBER(FIND("$",D11)),Справочники!$H$3,IF(ISNUMBER(FIND("€",D11)),Справочники!$H$4,1)) -> 10925 | L11: =IFERROR(VLOOKUP(TRIM(G11),Справочники!$D$3:$E$13,2,0),"Нет в справочнике") -> Отменен | M11: =IF(COUNTIFS($H$2:H11,H11,$I$2:I11,I11,$E$2:E11,E11)>1,"Дубликат","") | N11: =IFERROR(VLOOKUP(I11,Товары_очищенные!$H$2:$J$502,3,0),"Нет в каталоге") -> Смартфоны | O11: =IFERROR(VLOOKUP(I11,Товары_очищенные!$H$2:$M$502,6,0),"") -> 58500 | P11: =IF(O11="","Нет в каталоге",IF(ABS(K11/O11-1)<=0.2,"ОК","Цена отличается от каталога")) -> Цена отличается от каталога
A12: 01/20/2025 | B12: АРТ_478 | C12: 3 | D12: €80 | E12: C0011 | F12: P014 | G12: возврат | H12: =DATE(VALUE(RIGHT(A12,4)),VALUE(LEFT(A12,2)),VALUE(MID(A12,4,2))) -> 45677 | I12: ="АРТ-"&TEXT(VALUE(LEFT(SUBSTITUTE(SUBSTITUTE(SUBSTITUTE(SUBSTITUTE(TRIM(B12),"№",""),"АРТ-",""),"АРТ_",""),"АРТ",""),3)),"000") -> АРТ-478 | J12: =VALUE(TRIM(SUBSTITUTE(SUBSTITUTE(TRIM(C12),"шт.",""),"шт",""))) -> 3 | K12: =VALUE(SUBSTITUTE(SUBSTITUTE(SUBSTITUTE(SUBSTITUTE(D12,"$",""),"€",""),"₽","")," ",""))*IF(ISNUMBER(FIND("$",D12)),Справочники!$H$3,IF(ISNUMBER(FIND("€",D12)),Справочники!$H$4,1)) -> 8000 | L12: =IFERROR(VLOOKUP(TRIM(G12),Справочники!$D$3:$E$13,2,0),"Нет в справочнике") -> Возврат | M12: =IF(COUNTIFS($H$2:H12,H12,$I$2:I12,I12,$E$2:E12,E12)>1,"Дубликат","") | N12: =IFERROR(VLOOKUP(I12,Товары_очищенные!$H$2:$J$502,3,0),"Нет в каталоге") -> Аксессуары | O12: =IFERROR(VLOOKUP(I12,Товары_очищенные!$H$2:$M$502,6,0),"") -> 12990 | P12: =IF(O12="","Нет в каталоге",IF(ABS(K12/O12-1)<=0.2,"ОК","Цена отличается от каталога")) -> Цена отличается от каталога
A13: 01/20/2025 | B13: 045-24 | C13: 1 | D13: 8500 ₽ | E13: C0012 | F13: P028 | G13: Завершен | H13: =DATE(VALUE(RIGHT(A13,4)),VALUE(LEFT(A13,2)),VALUE(MID(A13,4,2))) -> 45677 | I13: ="АРТ-"&TEXT(VALUE(LEFT(SUBSTITUTE(SUBSTITUTE(SUBSTITUTE(SUBSTITUTE(TRIM(B13),"№",""),"АРТ-",""),"АРТ_",""),"АРТ",""),3)),"000") -> АРТ-045 | J13: =VALUE(TRIM(SUBSTITUTE(SUBSTITUTE(TRIM(C13),"шт.",""),"шт",""))) -> 1 | K13: =VALUE(SUBSTITUTE(SUBSTITUTE(SUBSTITUTE(SUBSTITUTE(D13,"$",""),"€",""),"₽","")," ",""))*IF(ISNUMBER(FIND("$",D13)),Справочники!$H$3,IF(ISNUMBER(FIND("€",D13)),Справочники!$H$4,1)) -> 8500 | L13: =IFERROR(VLOOKUP(TRIM(G13),Справочники!$D$3:$E$13,2,0),"Нет в справочнике") -> Завершен | M13: =IF(COUNTIFS($H$2:H13,H13,$I$2:I13,I13,$E$2:E13,E13)>1,"Дубликат","") | N13: =IFERROR(VLOOKUP(I13,Товары_очищенные!$H$2:$J$502,3,0),"Нет в каталоге") -> Телевизоры | O13: =IFERROR(VLOOKUP(I13,Товары_очищенные!$H$2:$M$502,6,0),"") -> 137000 | P13: =IF(O13="","Нет в каталоге",IF(ABS(K13/O13-1)<=0.2,"ОК","Цена отличается от каталога")) -> Цена отличается от каталога
... A1001: 05/29/2026 | B1001: №АРТ-357 | C1001: -3 | D1001: $120 | E1001: C1000 | F1001: P030 | G1001: завершен | H1001: =DATE(VALUE(RIGHT(A1001,4)),VALUE(LEFT(A1001,2)),VALUE(MID(A1001,4,2))) -> 46171 | I1001: ="АРТ-"&TEXT(VALUE(LEFT(SUBSTITUTE(SUBSTITUTE(SUBSTITUTE(SUBSTITUTE(TRIM(B1001),"№",""),"АРТ-",""),"АРТ_",""),"АРТ",""),3)),"000") -> АРТ-357 | J1001: =VALUE(TRIM(SUBSTITUTE(SUBSTITUTE(TRIM(C1001),"шт.",""),"шт",""))) -> -3 | K1001: =VALUE(SUBSTITUTE(SUBSTITUTE(SUBSTITUTE(SUBSTITUTE(D1001,"$",""),"€",""),"₽","")," ",""))*IF(ISNUMBER(FIND("$",D1001)),Справочники!$H$3,IF(ISNUMBER(FIND("€",D1001)),Справочники!$H$4,1)) -> 11400 | L1001: =IFERROR(VLOOKUP(TRIM(G1001),Справочники!$D$3:$E$13,2,0),"Нет в справочнике") -> Завершен | M1001: =IF(COUNTIFS($H$2:H1001,H1001,$I$2:I1001,I1001,$E$2:E1001,E1001)>1,"Дубликат","") | N1001: =IFERROR(VLOOKUP(I1001,Товары_очищенные!$H$2:$J$502,3,0),"Нет в каталоге") -> Смартфоны | O1001: =IFERROR(VLOOKUP(I1001,Товары_очищенные!$H$2:$M$502,6,0),"") -> 88000 | P1001: =IF(O1001="","Нет в каталоге",IF(ABS(K1001/O1001-1)<=0.2,"ОК","Цена отличается от каталога")) -> Цена отличается от каталога

Sheet Клиенты_очищенные
A1: ID_клиента (исх.) | B1: ФИО (исх.) | C1: Дата_рождения (исх.) | D1: Телефон (исх.) | E1: Email (исх.) | F1: Город (исх.) | G1: Дата_регистрации (исх.) | H1: ФИО | I1: Дата рождения | J1: Возраст | K1: Проверка даты рождения | L1: Дата регистрации | M1: Телефон | N1: Email | O1: Проверка Email | P1: Город
A2: C0001 | B2: Иванов Иван Иванович | C2: 15.05.1990 | D2: 8-903-123-45-67 | E2: ivanov@mail.ru | F2: Москва | G2: 01.01.2022 | H2: =PROPER(TRIM(B2)) -> Иванов Иван Иванович | I2: =IFERROR(IF(ISNUMBER(FIND("-",C2)),DATE(VALUE(LEFT(C2,4)),VALUE(MID(C2,6,2)),VALUE(RIGHT(C2,2))),IF(ISNUMBER(FIND(".",C2)),DATE(VALUE(RIGHT(C2,4)),VALUE(MID(C2,4,2)),VALUE(LEFT(C2,2))),DATE(VALUE(RIGHT(C2,4)),VLOOKUP(TRIM(MID(C2,FIND(" ",C2)+1,LEN(C2)-FIND(" ",C2)-5)),Справочники!$M$3:$N$14,2,0),VALUE(LEFT(C2,FIND(" ",C2)-1))))),"") -> 33008 | J2: =IF(I2="","",DATEDIF(I2,TODAY(),"Y")) -> 36 | K2: =IF(OR(I2="",J2<18,J2>120),"Ошибка даты рождения","ОК") -> ОК | L2: =IFERROR(IF(ISNUMBER(FIND("-",G2)),DATE(VALUE(LEFT(G2,4)),VALUE(MID(G2,6,2)),VALUE(RIGHT(G2,2))),IF(ISNUMBER(FIND(".",G2)),DATE(VALUE(RIGHT(G2,4)),VALUE(MID(G2,4,2)),VALUE(LEFT(G2,2))),DATE(VALUE(RIGHT(G2,4)),VLOOKUP(TRIM(MID(G2,FIND(" ",G2)+1,LEN(G2)-FIND(" ",G2)-5)),Справочники!$M$3:$N$14,2,0),VALUE(LEFT(G2,FIND(" ",G2)-1))))),"") -> 44562 | M2: =IF(LEN(SUBSTITUTE(SUBSTITUTE(SUBSTITUTE(SUBSTITUTE(SUBSTITUTE(D2,"+",""),"-","")," ",""),"(",""),")",""))<10,"Ошибка телефона","+7 ("&MID(RIGHT(SUBSTITUTE(SUBSTITUTE(SUBSTITUTE(SUBSTITUTE(SUBSTITUTE(D2,"+",""),"-","")," ",""),"(",""),")",""),10),1,3)&") "&MID(RIGHT(SUBSTITUTE(SUBSTITUTE(SUBSTITUTE(SUBSTITUTE(SUBSTITUTE(D2,"+",""),"-","")," ",""),"(",""),")",""),10),4,3)&"-"&MID(RIGHT(SUBSTITUTE(SUBSTITUTE(SUBSTITUTE(SUBSTITUTE(SUBSTITUTE(D2,"+",""),"-","")," ",""),"(",""),")",""),10),7,2)&"-"&RIGHT(SUBSTITUTE(SUBSTITUTE(SUBSTITUTE(SUBSTITUTE(SUBSTITUTE(D2,"+",""),"-","")," ",""),"(",""),")",""),2)) -> +7 (903) 123-45-67 | N2: =LOWER(SUBSTITUTE(TRIM(E2)," ","")) -> ivanov@mail.ru | O2: =IF(AND(ISNUMBER(FIND("@",N2)),ISNUMBER(FIND(".",N2,FIND("@",N2)+2))),"ОК","Ошибка Email") -> ОК | P2: =IFERROR(VLOOKUP(TRIM(SUBSTITUTE(SUBSTITUTE(" "&F2," г "," "),"г.","")),Справочники!$J$3:$K$102,2,0),TRIM(SUBSTITUTE(SUBSTITUTE(" "&F2," г "," "),"г.",""))) -> Москва
A3: C0002 | B3: Петров Петр Петрович | C3: 23.08.1985 | D3: +7 903 234-56-78 | E3: petrov@yandex | F3: Санкт-Петербург | G3: 2022-01-15 | H3: =PROPER(TRIM(B3)) -> Петров Петр Петрович | I3: =IFERROR(IF(ISNUMBER(FIND("-",C3)),DATE(VALUE(LEFT(C3,4)),VALUE(MID(C3,6,2)),VALUE(RIGHT(C3,2))),IF(ISNUMBER(FIND(".",C3)),DATE(VALUE(RIGHT(C3,4)),VALUE(MID(C3,4,2)),VALUE(LEFT(C3,2))),DATE(VALUE(RIGHT(C3,4)),VLOOKUP(TRIM(MID(C3,FIND(" ",C3)+1,LEN(C3)-FIND(" ",C3)-5)),Справочники!$M$3:$N$14,2,0),VALUE(LEFT(C3,FIND(" ",C3)-1))))),"") -> 31282 | J3: =IF(I3="","",DATEDIF(I3,TODAY(),"Y")) -> 41 | K3: =IF(OR(I3="",J3<18,J3>120),"Ошибка даты рождения","ОК") -> ОК | L3: =IFERROR(IF(ISNUMBER(FIND("-",G3)),DATE(VALUE(LEFT(G3,4)),VALUE(MID(G3,6,2)),VALUE(RIGHT(G3,2))),IF(ISNUMBER(FIND(".",G3)),DATE(VALUE(RIGHT(G3,4)),VALUE(MID(G3,4,2)),VALUE(LEFT(G3,2))),DATE(VALUE(RIGHT(G3,4)),VLOOKUP(TRIM(MID(G3,FIND(" ",G3)+1,LEN(G3)-FIND(" ",G3)-5)),Справочники!$M$3:$N$14,2,0),VALUE(LEFT(G3,FIND(" ",G3)-1))))),"") -> 44576 | M3: =IF(LEN(SUBSTITUTE(SUBSTITUTE(SUBSTITUTE(SUBSTITUTE(SUBSTITUTE(D3,"+",""),"-","")," ",""),"(",""),")",""))<10,"Ошибка телефона","+7 ("&MID(RIGHT(SUBSTITUTE(SUBSTITUTE(SUBSTITUTE(SUBSTITUTE(SUBSTITUTE(D3,"+",""),"-","")," ",""),"(",""),")",""),10),1,3)&") "&MID(RIGHT(SUBSTITUTE(SUBSTITUTE(SUBSTITUTE(SUBSTITUTE(SUBSTITUTE(D3,"+",""),"-","")," ",""),"(",""),")",""),10),4,3)&"-"&MID(RIGHT(SUBSTITUTE(SUBSTITUTE(SUBSTITUTE(SUBSTITUTE(SUBSTITUTE(D3,"+",""),"-","")," ",""),"(",""),")",""),10),7,2)&"-"&RIGHT(SUBSTITUTE(SUBSTITUTE(SUBSTITUTE(SUBSTITUTE(SUBSTITUTE(D3,"+",""),"-","")," ",""),"(",""),")",""),2)) -> +7 (903) 234-56-78 | N3: =LOWER(SUBSTITUTE(TRIM(E3)," ","")) -> petrov@yandex | O3: =IF(AND(ISNUMBER(FIND("@",N3)),ISNUMBER(FIND(".",N3,FIND("@",N3)+2))),"ОК","Ошибка Email") -> Ошибка Email | P3: =IFERROR(VLOOKUP(TRIM(SUBSTITUTE(SUBSTITUTE(" "&F3," г "," "),"г.","")),Справочники!$J$3:$K$102,2,0),TRIM(SUBSTITUTE(SUBSTITUTE(" "&F3," г "," "),"г.",""))) -> Санкт-Петербург
A4: C0003 | B4: Сидоров Сидор Сидорович | C4: 12.03.1992 | D4: 8 903 345 67 89 | E4: sidorov@gmail.com | F4: Екатеринбург | G4: 15.01.2022 | H4: =PROPER(TRIM(B4)) -> Сидоров Сидор Сидорович | I4: =IFERROR(IF(ISNUMBER(FIND("-",C4)),DATE(VALUE(LEFT(C4,4)),VALUE(MID(C4,6,2)),VALUE(RIGHT(C4,2))),IF(ISNUMBER(FIND(".",C4)),DATE(VALUE(RIGHT(C4,4)),VALUE(MID(C4,4,2)),VALUE(LEFT(C4,2))),DATE(VALUE(RIGHT(C4,4)),VLOOKUP(TRIM(MID(C4,FIND(" ",C4)+1,LEN(C4)-FIND(" ",C4)-5)),Справочники!$M$3:$N$14,2,0),VALUE(LEFT(C4,FIND(" ",C4)-1))))),"") -> 33675 | J4: =IF(I4="","",DATEDIF(I4,TODAY(),"Y")) -> 34 | K4: =IF(OR(I4="",J4<18,J4>120),"Ошибка даты рождения","ОК") -> ОК | L4: =IFERROR(IF(ISNUMBER(FIND("-",G4)),DATE(VALUE(LEFT(G4,4)),VALUE(MID(G4,6,2)),VALUE(RIGHT(G4,2))),IF(ISNUMBER(FIND(".",G4)),DATE(VALUE(RIGHT(G4,4)),VALUE(MID(G4,4,2)),VALUE(LEFT(G4,2))),DATE(VALUE(RIGHT(G4,4)),VLOOKUP(TRIM(MID(G4,FIND(" ",G4)+1,LEN(G4)-FIND(" ",G4)-5)),Справочники!$M$3:$N$14,2,0),VALUE(LEFT(G4,FIND(" ",G4)-1))))),"") -> 44576 | M4: =IF(LEN(SUBSTITUTE(SUBSTITUTE(SUBSTITUTE(SUBSTITUTE(SUBSTITUTE(D4,"+",""),"-","")," ",""),"(",""),")",""))<10,"Ошибка телефона","+7 ("&MID(RIGHT(SUBSTITUTE(SUBSTITUTE(SUBSTITUTE(SUBSTITUTE(SUBSTITUTE(D4,"+",""),"-","")," ",""),"(",""),")",""),10),1,3)&") "&MID(RIGHT(SUBSTITUTE(SUBSTITUTE(SUBSTITUTE(SUBSTITUTE(SUBSTITUTE(D4,"+",""),"-","")," ",""),"(",""),")",""),10),4,3)&"-"&MID(RIGHT(SUBSTITUTE(SUBSTITUTE(SUBSTITUTE(SUBSTITUTE(SUBSTITUTE(D4,"+",""),"-","")," ",""),"(",""),")",""),10),7,2)&"-"&RIGHT(SUBSTITUTE(SUBSTITUTE(SUBSTITUTE(SUBSTITUTE(SUBSTITUTE(D4,"+",""),"-","")," ",""),"(",""),")",""),2)) -> +7 (903) 345-67-89 | N4: =LOWER(SUBSTITUTE(TRIM(E4)," ","")) -> sidorov@gmail.com | O4: =IF(AND(ISNUMBER(FIND("@",N4)),ISNUMBER(FIND(".",N4,FIND("@",N4)+2))),"ОК","Ошибка Email") -> ОК | P4: =IFERROR(VLOOKUP(TRIM(SUBSTITUTE(SUBSTITUTE(" "&F4," г "," "),"г.","")),Справочники!$J$3:$K$102,2,0),TRIM(SUBSTITUTE(SUBSTITUTE(" "&F4," г "," "),"г.",""))) -> Екатеринбург
